Workbook
Name CPRAMขอยกเลิก: 'Drop down list สาเหตุที่หยุด'!$G$2:$G$9
Name Merหรือลูกค้าขอยกเลิก: 'Drop down list สาเหตุที่หยุด'!$F$2:$F$9
Name มีConceptจากMktของCPRAMมาให้แต่เสนอConceptแล้วไม่ผ่าน: 'Drop down list สาเหตุที่หยุด'!$B$2:$B$9
Name มีConceptจากลูกค้ามาให้แต่เสนอConceptแล้วไม่ผ่าน: 'Drop down list สาเหตุที่หยุด'!$C$2:$C$9
Name ไม่ผ่านในขั้นตอนScreenTest: 'Drop down list สาเหตุที่หยุด'!$E$2:$E$9
Name ไม่มีConceptแต่เสนอสินค้าแล้วไม่ผ่าน: 'Drop down list สาเหตุที่หยุด'!$D$2:$D$9
Name อื่นๆ: 'Drop down list สาเหตุที่หยุด'!$H$2:$H$9

Sheet Dashboard
A1: Dashboard - สรุปภาพรวม RTE 2026
A3: Total Plan New | B3: =SUM('%success ทุกเดือน'!D4:D1000)
A4: Total Sold New | B4: =SUM('%success ทุกเดือน'!F4:F1000)
A5: % Success New (Overall) | B5: =IFERROR(B4/B3,"")
A6: Total Stop Planned | B6: =SUM('%success ทุกเดือน'!H4:H1000)
A7: Total Stop Unplanned | B7: =SUM('%success ทุกเดือน'!I4:I1000)
A9: Month | B9: Plan New | C9: Sold New | D9: % Success
A10: Jan | B10: =SUMIFS('%success ทุกเดือน'!$D:$D,'%success ทุกเดือน'!$C:$C,"Jan") | C10: =SUMIFS('%success ทุกเดือน'!$F:$F,'%success ทุกเดือน'!$C:$C,"Jan") | D10: =IFERROR(C10/B10,"")
A11: Feb | B11: =SUMIFS('%success ทุกเดือน'!$D:$D,'%success ทุกเดือน'!$C:$C,"Feb") | C11: =SUMIFS('%success ทุกเดือน'!$F:$F,'%success ทุกเดือน'!$C:$C,"Feb") | D11: =IFERROR(C11/B11,"")
A12: Mar | B12: =SUMIFS('%success ทุกเดือน'!$D:$D,'%success ทุกเดือน'!$C:$C,"Mar") | C12: =SUMIFS('%success ทุกเดือน'!$F:$F,'%success ทุกเดือน'!$C:$C,"Mar") | D12: =IFERROR(C12/B12,"")
A13: Apr | B13: =SUMIFS('%success ทุกเดือน'!$D:$D,'%success ทุกเดือน'!$C:$C,"Apr") | C13: =SUMIFS('%success ทุกเดือน'!$F:$F,'%success ทุกเดือน'!$C:$C,"Apr") | D13: =IFERROR(C13/B13,"")
A14: May | B14: =SUMIFS('%success ทุกเดือน'!$D:$D,'%success ทุกเดือน'!$C:$C,"May") | C14: =SUMIFS('%success ทุกเดือน'!$F:$F,'%success ทุกเดือน'!$C:$C,"May") | D14: =IFERROR(C14/B14,"")
A15: Jun | B15: =SUMIFS('%success ทุกเดือน'!$D:$D,'%success ทุกเดือน'!$C:$C,"Jun") | C15: =SUMIFS('%success ทุกเดือน'!$F:$F,'%success ทุกเดือน'!$C:$C,"Jun") | D15: =IFERROR(C15/B15,"")
A16: Jul | B16: =SUMIFS('%success ทุกเดือน'!$D:$D,'%success ทุกเดือน'!$C:$C,"Jul") | C16: =SUMIFS('%success ทุกเดือน'!$F:$F,'%success ทุกเดือน'!$C:$C,"Jul") | D16: =IFERROR(C16/B16,"")
A17: Aug | B17: =SUMIFS('%success ทุกเดือน'!$D:$D,'%success ทุกเดือน'!$C:$C,"Aug") | C17: =SUMIFS('%success ทุกเดือน'!$F:$F,'%success ทุกเดือน'!$C:$C,"Aug") | D17: =IFERROR(C17/B17,"")
A18: Sep | B18: =SUMIFS('%success ทุกเดือน'!$D:$D,'%success ทุกเดือน'!$C:$C,"Sep") | C18: =SUMIFS('%success ทุกเดือน'!$F:$F,'%success ทุกเดือน'!$C:$C,"Sep") | D18: =IFERROR(C18/B18,"")
A19: Oct | B19: =SUMIFS('%success ทุกเดือน'!$D:$D,'%success ทุกเดือน'!$C:$C,"Oct") | C19: =SUMIFS('%success ทุกเดือน'!$F:$F,'%success ทุกเดือน'!$C:$C,"Oct") | D19: =IFERROR(C19/B19,"")
A20: Nov | B20: =SUMIFS('%success ทุกเดือน'!$D:$D,'%success ทุกเดือน'!$C:$C,"Nov") | C20: =SUMIFS('%success ทุกเดือน'!$F:$F,'%success ทุกเดือน'!$C:$C,"Nov") | D20: =IFERROR(C20/B20,"")
A21: Dec | B21: =SUMIFS('%success ทุกเดือน'!$D:$D,'%success ทุกเดือน'!$C:$C,"Dec") | C21: =SUMIFS('%success ทุกเดือน'!$F:$F,'%success ทุกเดือน'!$C:$C,"Dec") | D21: =IFERROR(C21/B21,"")
A23: ฟอร์มเพิ่มรายการสินค้าใหม่
A24: กลุ่มสินค้า
A25: ตลาด
A26: ส่งออกและ non7 ให้ใส่ชื่อลูกค้าด้วย
A27: ชื่อสินค้า
A28: ตาม/นอกแผน
A29: เดือนที่หยุดพัฒนา
A30: สาเหตุ
A31: เนื่องจาก

Sheet สำหรับพี่กรณ์
A1: Performance Jan-Aug 2023
B3: PMA | C3: Group | D3: ขายได้ | E3: % | F3: หยุดพัฒนา | G3: % | H3: พัฒนาทั้งหมด
A4: พี่ผึ้ง | B4: PMA02 | C4: FULLY FRIED | D4: 1 | E4: =D4/H4% | F4: 1 | G4: =F4/H4% | H4: =D4+F4
B5: PMA08 | C5: BURGER Stk Rice | D5: 9 | E5: =(D5+D6)/H5% | F5: 0 | G5: =F5/H5% | H5: =D5+F5+D6
C6: BURGER | D6: 3
B7: PMA22 ข้าวเหนียว | C7: Steak | D7: 1 | E7: =(D7+D8)/H7% | F7: 0 | G7: =F7/H7% | H7: =D7+D8+F7
C8: Sticky Rice | D8: 1
B9: PMA20 เกี๊ยว | C9: Dumpling | D9: 1 | E9: =D9/H9% | F9: 0 | G9: =F9/H9% | H9: =D9+F9
A10: Total | D10: =SUM(D4:D9) | E10: =D10/H10% | F10: =SUM(F4:F9) | G10: =F10/H10% | H10: =SUM(H4:H9)
A11: พี่หญิงสุ | B11: PMA24 | C11: MINIPAO | D11: 3 | E11: =(D11+D12+D13+D14+D15+D16)/H11% | F11: 11 | G11: =F11/H11% | H11: =D11+D12+D13+D14+D15+D16+F11
C12: PAOPAO | D12: 6
C13: SALAPAO | D13: 6
C14: BIGPAO | D14: 1
C15: SHUMAI(stk) | D15: 3
C16: SHUMAI(chill) | D16: 4
A17: Total | D17: =SUM(D11:D16) | E17: =D17/H17% | F17: =SUM(F11:F16) | G17: =F17/H17% | H17: =SUM(H11:H16)
A18: พี่แพท | B18: PMA16 | C18: สลัด | D18: 1 | E18: =D18/H18% | F18: 0 | G18: =F18/H18% | H18: =D18+F18
A19: Total | D19: =SUM(D18) | E19: =D19/H19% | F19: =SUM(F18) | G19: =F19/H19% | H19: =SUM(H18)
A20: หมิว | B20: PMA19 ข้าวปั้น | C20: ข้าวปั้น | D20: 1 | E20: =D20/H20% | F20: 1 | G20: =F20/H20% | H20: =D20+F20
A21: Total | D21: =SUM(D20) | E21: =D21/H21% | F21: =SUM(F20) | G21: =F21/H21% | H21: =SUM(H20)
A22: พี่อ้อมใจ | B22: PMA19 Chilled | C22: กลุ่มเส้น | D22: 6 | E22: =(D22+D23+D24+D25+D26+D27)/H22% | F22: 0 | G22: =F22/H22% | H22: =D22+D23+D24+D25+D26+D27+F22
C23: กับข้าว | D23: 6
C24: ข้าว-กับข้าว | D24: 8
C25: ข้าวผัด | D25: 5
C26: โจ๊ก | D26: 2
C27: กลุ่มยำ | D27: 2
A28: Total | D28: =SUM(D22:D27) | E28: =D28/H28% | F28: =SUM(F22) | G28: =F28/H28% | H28: =SUM(H22:H27)
A29: พี่อ๊อก&พี่หยิม | B29: PMA19 โครงการพิเศษ | D29: 0 | E29: =D29/H29% | F29: 6 | G29: =F29/H29% | H29: =D29+F29
B30: PMA22 โครงการพิเศษ | C30: ข้าว-กับข้าว | D30: 1 | E30: =D30/H30% | F30: 0 | G30: =F30/H30% | H30: =D30+F30
B31: PMA06 โครงการพิเศษ | C31: RM | D31: 1 | E31: =(D31+D32)/H31% | F31: 4 | G31: =F31/H31% | H31: =D31+D32+F31
C32: Ready Meal | D32: 1
B33: non 7-11 โครงการพิเศษ | C33: กับข้าว | D33: 6 | E33: =D33/H33% | F33: 3 | G33: =F33/H33% | H33: =D33+D34+D35+F33
C34: ข้าว-กับข้าว | D34: 2
C35: กลุ่มเส้น | D35: 1
A36: Total | D36: =SUM(D29:D35) | E36: =D36/H36% | F36: =SUM(F28:F35) | G36: =F36/H36% | H36: =SUM(H29:H35)
A37: พี่ส้ม | B37: PMA20 ข้าวFrozen | C37: ข้าว-กับข้าว | D37: 4 | E37: =(D37+D38+D39+D40+D41+D42)/H37% | F37: 29 | G37: =F37/H37% | H37: =D37+D38+D39+D40+D41+D42+F37
C38: ซุป | D38: 4
C39: เส้น | D39: 3
C40: กับข้าว | D40: 1
C41: ข้าว | D41: 1
...

Sheet %success ทุกเดือน ของเก่า
A1: จำนวนสินค้าใหม่ RTE Q1/2023
A2: กลุ่มสินค้า | B2: 44927 | L2: 44958 | V2: 44986 | AF2: Q1/2023
B3: แผนขาย | D3: ขายได้ | F3: หยุดพัฒนา | H3: พัฒนาทั้งหมด | I3: %success | L3: แผนขาย | N3: ขายได้ | P3: หยุดพัฒนา | R3: พัฒนาทั้งหมด | S3: %success | V3: แผนขาย | X3: ขายได้ | Z3: หยุดพัฒนา | AB3: พัฒนาทั้งหมด | AC3: %success
B4: New | C4: Imp | D4: New | E4: Imp | F4: ตามแผน | G4: นอกแผน | I4: New | J4: Imp | K4: รวม | L4: New | M4: Imp | N4: New | O4: Imp | P4: ตามแผน | Q4: นอกแผน | S4: New | T4: Imp | U4: รวม | V4: New | W4: Imp | X4: New | Y4: Imp | Z4: ตามแผน | AA4: นอกแผน | AC4: New | AD4: Imp | AE4: รวม
A5: PMA02 | B5: 0 | C5: 0 | D5: 0 | E5: 0 | H5: =SUM(D5:G5) | I5: 0 | J5: 0 | K5: 0 | L5: 0 | M5: 0 | N5: 0 | O5: 0 | R5: =SUM(N5:Q5) | S5: 0 | T5: 0 | U5: 0 | V5: 0 | W5: 0 | X5: 0 | Y5: 0 | AB5: =SUM(X5:AA5) | AC5: 0 | AD5: 0 | AE5: 0 | AF5: 0
A6: PMA08 | B6: 1 | C6: 0 | D6: 1 | E6: 0 | H6: =SUM(D6:G6) | I6: =D6/B6% | J6: 0 | K6: =(D6+E6)/(B6+C6)% | L6: 0 | M6: 1 | N6: 0 | O6: 1 | R6: =SUM(N6:Q6) | S6: 0 | T6: =O6/M6% | U6: =(N6+O6)/(L6+M6)% | V6: 0 | W6: 0 | X6: 0 | Y6: 0 | AB6: =SUM(X6:AA6) | AC6: 0 | AD6: 0 | AE6: 0 | AF6: =(D6+E6+N6+O6+X6+Y6)/(B6+C6+L6+M6+V6+W6)*100
A7: PMA22 ข้าวเหนียว | B7: 0 | C7: 0 | D7: 0 | E7: 0 | H7: =SUM(D7:G7) | I7: 0 | J7: 0 | K7: 0 | L7: 0 | M7: 0 | N7: 0 | O7: 0 | R7: =SUM(N7:Q7) | S7: 0 | T7: 0 | U7: 0 | V7: 0 | W7: 0 | X7: 0 | Y7: 0 | AB7: =SUM(X7:AA7) | AC7: 0 | AD7: 0 | AE7: 0 | AF7: 0
A8: PMA24 | B8: 2 | C8: 0 | D8: 2 | E8: 0 | G8: 1 | H8: =SUM(D8:G8) | I8: =D8/B8% | J8: 0 | K8: =(D8+E8)/(B8+C8)% | L8: 2 | M8: 1 | N8: 2 | O8: 1 | Q8: 1 | R8: =SUM(N8:Q8) | S8: =N8/L8% | T8: =O8/M8% | U8: =(N8+O8)/(L8+M8)% | V8: 0 | W8: 0 | X8: 0 | Y8: 0 | AB8: =SUM(X8:AA8) | AC8: 0 | AD8: 0 | AE8: 0 | AF8: =(D8+E8+N8+O8+X8+Y8)/(B8+C8+L8+M8+V8+W8)*100
A9: PMA16 | B9: 0 | C9: 0 | D9: 0 | E9: 0 | H9: =SUM(D9:G9) | I9: 0 | J9: 0 | K9: 0 | L9: 1 | M9: 0 | N9: 1 | O9: 0 | R9: =SUM(N9:Q9) | S9: =N9/L9% | T9: 0 | U9: =(N9+O9)/(L9+M9)% | V9: 0 | W9: 0 | X9: 0 | Y9: 0 | AB9: =SUM(X9:AA9) | AC9: 0 | AD9: 0 | AE9: 0 | AF9: =(D9+E9+N9+O9+X9+Y9)/(B9+C9+L9+M9+V9+W9)*100
A10: PMA19 ข้าวปั้น | B10: 0 | C10: 0 | D10: 0 | E10: 0 | H10: =SUM(D10:G10) | I10: 0 | J10: 0 | K10: 0 | L10: 0 | M10: 0 | N10: 0 | O10: 0 | Q10: 1 | R10: =SUM(N10:Q10) | S10: 0 | T10: 0 | U10: 0 | V10: 0 | W10: 0 | X10: 0 | Y10: 0 | AB10: =SUM(X10:AA10) | AC10: 0 | AD10: 0 | AE10: 0 | AF10: 0
A11: PMA19 Chilled | B11: 9 | C11: 0 | D11: 9 | E11: 0 | H11: =SUM(D11:G11) | I11: =D11/B11% | J11: 0 | K11: =(D11+E11)/(B11+C11)% | L11: 2 | M11: 0 | N11: 2 | O11: 0 | R11: =SUM(N11:Q11) | S11: =N11/L11% | T11: 0 | U11: =(N11+O11)/(L11+M11)% | V11: 1 | W11: 0 | X11: 1 | Y11: 0 | AB11: =SUM(X11:AA11) | AC11: =X11/V11% | AD11: 0 | AE11: =(X11+Y11)/(V11+W11)% | AF11: =(D11+E11+N11+O11+X11+Y11)/(B11+C11+L11+M11+V11+W11)*100
A12: PMA19 โครงการพิเศษ | B12: 0 | C12: 0 | D12: 0 | E12: 0 | G12: 6 | H12: =SUM(D12:G12) | I12: 0 | J12: 0 | K12: 0 | L12: 0 | M12: 0 | N12: 0 | O12: 0 | R12: =SUM(N12:Q12) | S12: 0 | T12: 0 | U12: 0 | V12: 0 | W12: 0 | X12: 0 | Y12: 0 | AB12: =SUM(X12:AA12) | AC12: 0 | AD12: 0 | AE12: 0 | AF12: 0
A13: PMA22 ข้าว Chilled | B13: 0 | C13: 0 | D13: 0 | E13: 0 | H13: =SUM(D13:G13) | I13: 0 | J13: 0 | K13: 0 | L13: 0 | M13: 0 | N13: 0 | O13: 0 | R13: =SUM(N13:Q13) | S13: 0 | T13: 0 | U13: 0 | V13: 0 | W13: 0 | X13: 0 | Y13: 0 | AB13: =SUM(X13:AA13) | AC13: 0 | AD13: 0 | AE13: 0 | AF13: 0
A14: PMA22 โครงการพิเศษ | B14: 0 | C14: 0 | D14: 0 | E14: 0 | H14: =SUM(D14:G14) | I14: 0 | J14: 0 | K14: 0 | L14: 0 | M14: 0 | N14: 0 | O14: 0 | R14: =SUM(N14:Q14) | S14: 0 | T14: 0 | U14: 0 | V14: 0 | W14: 0 | X14: 0 | Y14: 0 | AB14: =SUM(X14:AA14) | AC14: 0 | AD14: 0 | AE14: 0 | AF14: 0
A15: PMA20 ข้าวFrozen | B15: 0 | C15: 0 | D15: 0 | E15: 0 | G15: 1 | H15: =SUM(D15:G15) | I15: 0 | J15: 0 | K15: 0 | L15: 2 | M15: 0 | N15: 2 | O15: 0 | Q15: 1 | R15: =SUM(N15:Q15) | S15: =N15/L15% | T15: 0 | U15: =(N15+O15)/(L15+M15)% | V15: 2 | W15: 3 | X15: 2 | Y15: 3 | AA15: 3 | AB15: =SUM(X15:AA15) | AC15: =X15/V15% | AD15: =Y15/W15% | AE15: =(X15+Y15)/(V15+W15)% | AF15: =(D15+E15+N15+O15+X15+Y15)/(B15+C15+L15+M15+V15+W15)*100
A16: PMA20 ทอด | B16: 0 | C16: 0 | D16: 0 | E16: 0 | H16: =SUM(D16:G16) | I16: 0 | J16: 0 | K16: 0 | L16: 0 | M16: 0 | N16: 0 | O16: 0 | R16: =SUM(N16:Q16) | S16: 0 | T16: 0 | U16: 0 | V16: 0 | W16: 0 | X16: 0 | Y16: 0 | AB16: =SUM(X16:AA16) | AC16: 0 | AD16: 0 | AE16: 0 | AF16: 0
A17: PMA06 ทอด | B17: 0 | C17: 0 | D17: 0 | E17: 0 | H17: =SUM(D17:G17) | I17: 0 | J17: 0 | K17: 0 | L17: 0 | M17: 0 | N17: 0 | O17: 0 | R17: =SUM(N17:Q17) | S17: 0 | T17: 0 | U17: 0 | V17: 0 | W17: 0 | X17: 0 | Y17: 0 | AB17: =SUM(X17:AA17) | AC17: 0 | AD17: 0 | AE17: 0 | AF17: 0
A18: PMA06 โครงการพิเศษ | B18: 0 | C18: 0 | D18: 0 | E18: 0 | G18: 2 | H18: =SUM(D18:G18) | I18: 0 | J18: 0 | K18: 0 | L18: 1 | M18: 0 | N18: 1 | O18: 0 | R18: =SUM(N18:Q18) | S18: =N18/L18% | T18: 0 | U18: =(N18+O18)/(L18+M18)% | V18: 0 | W18: 0 | X18: 0 | Y18: 0 | AB18: =SUM(X18:AA18) | AC18: 0 | AD18: 0 | AE18: 0 | AF18: =(D18+E18+N18+O18+X18+Y18)/(B18+C18+L18+M18+V18+W18)*100
A19: PMA76 โครงการพิเศษ | B19: 0 | C19: 0 | D19: 0 | E19: 0 | H19: =SUM(D19:Q19) | I19: 0 | J19: 0 | K19: 0 | L19: 0 | M19: 0 | N19: 0 | O19: 0 | R19: =SUM(N19:Q19) | S19: 0 | T19: 0 | U19: 0 | V19: 0 | W19: 0 | X19: 0 | Y19: 0 | AB19: =SUM(X19:AA19) | AC19: 0 | AD19: 0 | AE19: 0 | AF19: 0
A20: non 7-11 โครงการพิเศษ | B20: 0 | C20: 0 | D20: 0 | E20: 0 | G20: 2 | H20: =SUM(D20:G20) | I20: 0 | J20: 0 | K20: 0 | L20: 0 | M20: 0 | N20: 0 | O20: 0 | R20: =SUM(N20:Q20) | S20: 0 | T20: 0 | U20: 0 | V20: 0 | W20: 0 | X20: 0 | Y20: 0 | AB20: =SUM(X20:AA20) | AC20: 0 | AD20: 0 | AE20: 0 | AF20: 0
A21: ติ่มซำ non-7 ในประเทศ | B21: 0 | C21: 0 | D21: 0 | E21: 0 | H21: =SUM(D21:G21) | I21: 0 | J21: 0 | K21: 0 | L21: 0 | M21: 0 | N21: 0 | O21: 0 | R21: =SUM(N21:Q21) | S21: 0 | T21: 0 | U21: 0 | V21: 0 | W21: 0 | X21: 0 | Y21: 0 | AB21: =SUM(X21:AA21) | AC21: 0 | AD21: 0 | AE21: 0 | AF21: 0
A22: ส่งออก โครงการพิเศษ | B22: 0 | C22: 0 | D22: 0 | E22: 0 | H22: =SUM(D22:G22) | I22: 0 | J22: 0 | K22: 0 | L22: 0 | M22: 0 | N22: 0 | O22: 0 | R22: =SUM(N22:Q22) | S22: 0 | T22: 0 | U22: 0 | V22: 0 | W22: 0 | X22: 0 | Y22: 0 | AB22: =SUM(X22:AA22) | AC22: 0 | AD22: 0 | AE22: 0 | AF22: 0
A23: ส่่งออก ทีมข้าวFrozen | B23: 0 | C23: 0 | D23: 0 | E23: 0 | H23: =SUM(D23:G23) | I23: 0 | J23: 0 | K23: 0 | L23: 0 | M23: 0 | N23: 0 | O23: 0 | R23: =SUM(N23:Q23) | S23: 0 | T23: 0 | U23: 0 | V23: 0 | W23: 0 | X23: 0 | Y23: 0 | AB23: =SUM(X23:AA23) | AC23: 0 | AD23: 0 | AE23: 0 | AF23: 0
A24: ติ่มซำส่งออก | B24: 2 | C24: 0 | D24: 2 | E24: 0 | H24: =SUM(D24:G24) | I24: =D24/B24% | J24: 0 | K24: =(D24+E24)/(B24+C24)% | L24: 0 | M24: 0 | N24: 0 | O24: 0 | R24: =SUM(N24:Q24) | S24: 0 | T24: 0 | U24: 0 | V24: 1 | W24: 0 | X24: 1 | Y24: 0 | AA24: 25 | AB24: =SUM(X24:AA24) | AC24: =X24/V24% | AD24: 0 | AE24: =(X24+Y24)/(V24+W24)% | AF24: =(D24+E24+N24+O24+X24+Y24)/(B24+C24+L24+M24+V24+W24)*100
A25: Snack ส่งออก | B25: 2 | C25: 0 | D25: 2 | E25: 0 | H25: =SUM(D25:G25) | I25: =D25/B25% | J25: 0 | K25: =(D25+E25)/(B25+C25)% | L25: 0 | M25: 0 | N25: 0 | O25: 0 | Q25: 10 | R25: =SUM(N25:Q25) | S25: 0 | T25: 0 | U25: 0 | V25: 0 | W25: 0 | X25: 0 | Y25: 0 | AA25: 7 | AB25: =SUM(X25:AA25) | AC25: 0 | AD25: 0 | AE25: 0 | AF25: =(D25+E25+N25+O25+X25+Y25)/(B25+C25+L25+M25+V25+W25)*100
A26: Total | B26: =SUM(B5:B25) | C26: =SUM(C5:C25) | D26: =SUM(D5:D25) | E26: =SUM(E5:E25) | F26: =SUM(F5:F25) | G26: =SUM(G5:G25) | H26: =SUM(H5:H25) | I26: =D26/B26% | J26: 0 | K26: =(D26+E26)/(B26+C26)% | L26: =SUM(L5:L25) | M26: =SUM(M5:M25) | N26: =SUM(N5:N25) | O26: =SUM(O5:O25) | P26: =SUM(P5:P25) | Q26: =SUM(Q5:Q25) | R26: =SUM(R5:R25) | S26: =N26/L26% | T26: =O26/M26% | U26: =(N26+O26)/(L26+M26)% | V26: =SUM(V5:V25) | W26: =SUM(W5:W25) | X26: =SUM(X5:X25) | Y26: =SUM(Y5:Y25) | Z26: =SUM(Z5:Z25) | AA26: =SUM(AA5:AA25) | AB26: =SUM(AB5:AB25) | AC26: =X26/V26% | AD26: =Y26/W26% | AE26: =(X26+Y26)/(V26+W26)% | AF26: =((D26+E26+N26+ O26+X26+Y26))/((B26+C26+L26+M26+V26+W26))*100
A27: จำนวนสินค้าใหม่ RTE Q2/2023
A28: กลุ่มสินค้า | B28: 45017 | L28: 45047 | V28: 45078 | AF28: Q2/2023 | AG28: Q2 สะสม 2023
B29: แผนขาย | D29: ขายได้ | F29: หยุดพัฒนา | H29: พัฒนาทั้งหมด | I29: %success | L29: แผนขาย | N29: ขายได้ | P29: หยุดพัฒนา | R29: พัฒนาทั้งหมด | S29: %success | V29: แผนขาย | X29: ขายได้ | Z29: หยุดพัฒนา | AB29: พัฒนาทั้งหมด | AC29: %success
B30: New | C30: Imp | D30: New | E30: Imp | F30: ตามแผน | G30: นอกแผน | I30: New | J30: Imp | K30: รวม | L30: New | M30: Imp | N30: New | O30: Imp | P30: ตามแผน | Q30: นอกแผน | S30: New | T30: Imp | U30: รวม | V30: New | W30: Imp | X30: New | Y30: Imp | Z30: ตามแผน | AA30: นอกแผน | AC30: New | AD30: Imp | AE30: รวม
A31: PMA02 | B31: 1 | C31: 0 | D31: 1 | E31: 0 | H31: =SUM(D31:G31) | I31: =D31/B31% | J31: 0 | K31: =(D31+E31)/(B31+C31)% | L31: 0 | M31: 0 | N31: 0 | O31: 0 | R31: =SUM(N31:Q31) | S31: 0 | T31: 0 | U31: 0 | V31: 0 | W31: 0 | X31: 0 | Y31: 0 | AA31: 1 | AB31: =SUM(X31:AA31) | AC31: 0 | AD31: 0 | AE31: 0 | AF31: =(D31+E31+N31+O31+X31+Y31)/(B31+C31+L31+M31+V31+W31)*100 | AG31: =(D5+E5+N5+O5+X5+Y5+D31+E31+N31+O31+X31+Y31)/(B5+C5+L5+M5+V5+W5+B31+C31+L31+M31+V31+W31)*100
A32: PMA08 | B32: 2 | C32: 3 | D32: 2 | E32: 3 | H32: =SUM(D32:G32) | I32: =D32/B32% | J32: =E32/C32% | K32: =(D32+E32)/(B32+C32)% | L32: 0 | M32: 1 | N32: 0 | O32: 1 | R32: =SUM(N32:Q32) | S32: 0 | T32: =O32/M32% | U32: =(N32+O32)/(L32+M32)% | V32: 0 | W32: 1 | X32: 0 | Y32: 1 | AB32: =SUM(X32:AA32) | AC32: 0 | AD32: =Y32/W32% | AE32: =(X32+Y32)/(V32+W32)% | AF32: =(D32+E32+N32+O32+X32+Y32)/(B32+C32+L32+M32+V32+W32)*100 | AG32: =(D6+E6+N6+O6+X6+Y6+D32+E32+N32+O32+X32+Y32)/(B6+C6+L6+M6+V6+W6+B32+C32+L32+M32+V32+W32)*100
A33: PMA22 ข้าวเหนียว | B33: 0 | C33: 0 | D33: 0 | E33: 0 | H33: =SUM(D33:G33) | I33: 0 | J33: 0 | K33: 0 | L33: 1 | M33: 0 | N33: 1 | O33: 0 | R33: =SUM(N33:Q33) | S33: =N33/L33% | T33: 0 | U33: =(N33+O33)/(L33+M33)% | V33: 0 | W33: 0 | X33: 0 | Y33: 0 | AB33: =SUM(X33:AA33) | AC33: 0 | AD33: 0 | AE33: 0 | AF33: =(D33+E33+N33+O33+X33+Y33)/(B33+C33+L33+M33+V33+W33)*100 | AG33: =(D7+E7+N7+O7+X7+Y7+D33+E33+N33+O33+X33+Y33)/(B7+C7+L7+M7+V7+W7+B33+C33+L33+M33+V33+W33)*100
A34: PMA24 | B34: 2 | C34: 0 | D34: 2 | E34: 0 | G34: 3 | H34: =SUM(D34:G34) | I34: =D34/B34% | J34: 0 | K34: =(D34+E34)/(B34+C34)% | L34: 3 | M34: 1 | N34: 3 | O34: 1 | R34: =SUM(N34:Q34) | S34: =N34/L34% | T34: =O34/M34% | U34: =(N34+O34)/(L34+M34)% | V34: 2 | W34: 0 | X34: 2 | Y34: 0 | AB34: 2 | AC34: =X34/V34% | AD34: 0 | AE34: =(X34+Y34)/(V34+W34)% | AF34: =(D34+E34+N34+O34+X34+Y34)/(B34+C34+L34+M34+V34+W34)*100 | AG34: =(D8+E8+N8+O8+X8+Y8+D34+E34+N34+O34+X34+Y34)/(B8+C8+L8+M8+V8+W8+B34+C34+L34+M34+V34+W34)*100
A35: PMA16 | B35: 0 | C35: 0 | D35: 0 | E35: 0 | H35: =SUM(D35:G35) | I35: 0 | J35: 0 | K35: 0 | L35: 0 | M35: 0 | N35: 0 | O35: 0 | R35: =SUM(N35:Q35) | S35: 0 | T35: 0 | U35: 0 | V35: 0 | W35: 0 | X35: 0 | Y35: 0 | AB35: =SUM(X35:AA35) | AC35: 0 | AD35: 0 | AE35: 0 | AF35: 0 | AG35: =(D9+E9+N9+O9+X9+Y9+D35+E35+N35+O35+X35+Y35)/(B9+C9+L9+M9+V9+W9+B35+C35+L35+M35+V35+W35)*100
A36: PMA19 ข้าวปั้น | B36: 1 | C36: 0 | D36: 1 | E36: 0 | H36: =SUM(D36:G36) | I36: =D36/B36% | J36: 0 | K36: =(D36+E36)/(B36+C36)% | L36: 0 | M36: 0 | N36: 0 | O36: 0 | R36: 0 | S36: 0 | T36: 0 | U36: 0 | V36: 0 | W36: 0 | X36: 0 | Y36: 0 | AB36: =SUM(X36:AA36) | AC36: 0 | AD36: 0 | AE36: 0 | AF36: =(D36+E36+N36+O36+X36+Y36)/(B36+C36+L36+M36+V36+W36)*100 | AG36: =(D10+E10+N10+O10+X10+Y10+D36+E36+N36+O36+X36+Y36)/(B10+C10+L10+M10+V10+W10+B36+C36+L36+M36+V36+W36)*100
A37: PMA19 Chilled | B37: 2 | C37: 0 | D37: 2 | E37: 0 | H37: =SUM(D37:G37) | I37: =D37/B37% | J37: 0 | K37: =(D37+E37)/(B37+C37)% | L37: 2 | M37: 1 | N37: 2 | O37: 1 | R37: =SUM(N37:Q37) | S37: =N37/L37% | T37: =O37/M37% | U37: =(N37+O37)/(L37+M37)% | V37: 0 | W37: 3 | X37: 0 | Y37: 3 | AB37: =SUM(X37:AA37) | AC37: 0 | AD37: =Y37/W37% | AE37: =(X37+Y37)/(V37+W37)% | AF37: =(D37+E37+N37+O37+X37+Y37)/(B37+C37+L37+M37+V37+W37)*100 | AG37: =(D11+E11+N11+O11+X11+Y11+D37+E37+N37+O37+X37+Y37)/(B11+C11+L11+M11+V11+W11+B37+C37+L37+M37+V37+W37)*100
A38: PMA19 โครงการพิเศษ | B38: 0 | C38: 0 | D38: 0 | E38: 0 | H38: =SUM(D38:G38) | I38: 0 | J38: 0 | K38: 0 | L38: 0 | M38: 0 | N38: 0 | O38: 0 | R38: =SUM(N38:Q38) | S38: 0 | T38: 0 | U38: 0 | V38: 0 | W38: 0 | X38: 0 | Y38: 0 | AB38: =SUM(X38:AA38) | AC38: 0 | AD38: 0 | AE38: 0 | AF38: 0 | AG38: 0
A39: PMA22 ข้าว Chilled | B39: 0 | C39: 0 | D39: 0 | E39: 0 | H39: =SUM(D39:G39) | I39: 0 | J39: 0 | K39: 0 | L39: 0 | M39: 0 | N39: 0 | O39: 0 | R39: =SUM(N39:Q39) | S39: 0 | T39: 0 | U39: 0 | V39: 0 | W39: 0 | X39: 0 | Y39: 0 | AB39: =SUM(X39:AA39) | AC39: 0 | AD39: 0 | AE39: 0 | AF39: 0 | AG39: 0
A40: PMA22 โครงการพิเศษ | B40: 1 | C40: 0 | D40: 1 | E40: 0 | H40: =SUM(D40:G40) | I40: =D40/B40% | J40: 0 | K40: =(D40+E40)/(B40+C40)% | L40: 0 | M40: 0 | N40: 0 | O40: 0 | R40: =SUM(N40:Q40) | S40: 0 | T40: 0 | U40: 0 | V40: 0 | W40: 0 | X40: 0 | Y40: 0 | AB40: =SUM(X40:AA40) | AC40: 0 | AD40: 0 | AE40: 0 | AF40: =(D40+E40+N40+O40+X40+Y40)/(B40+C40+L40+M40+V40+W40)*100 | AG40: =(D14+E14+N14+O14+X14+Y14+D40+E40+N40+O40+X40+Y40)/(B14+C14+L14+M14+V14+W14+B40+C40+L40+M40+V40+W40)*100
...

Sheet Drop down list เดือน ชื่อทีม
B3: ติ่มซำ (นึ่ง) | D3: Jan | F3: ตามแผน | H3: Export | J3: Q1 | L3: All Store | N3: สินค้าไม่ผ่าน | O3: Man | Q3: เข้าซ้ำ | S3: Q1
B4: เบอร์เกอร์ รองท้อง | D4: Feb | F4: นอกแผน | H4: non-7 | J4: Q2 | L4: ทดลองขาย | N4: product spec ไม่ตรง | O4: Machine | Q4: ไม่เข้าซ้ำ | S4: Q2
B5: ข้าวเหนียว สเต็ก | D5: Mar | H5: PMA02 | J5: Q3 | L5: บางสาขา | N5: กระบวนการไม่ผ่าน (PD) | O5: Material | S5: Q3
B6: ข้าวผัด ข้าวต้ม โจ๊ก | D6: Apr | H6: PMA06 | J6: Q4 | L6: non 7-11 | N6: กระบวนการไม่ผ่าน (ผลิต) | O6: Method | S6: Q4
B7: ข้าวและกับข้าว | D7: May | H7: PMA08 | L7: ต่างประเทศ | N7: GHP ไม่ผ่าน | O7: Environment
B8: กับข้าว | D8: Jun | H8: PMA16
B9: ข้าวปั้น เครื่องเคียง | D9: Jul | H9: PMA19
B10: เส้น (แป้งสาลี) ซุป | D10: Aug | H10: PMA20
B11: เส้น (ข้าวไทย) | D11: Sep | H11: PMA22
B12: สลัด ยำ น้ำจิ้ม | D12: Oct | H12: PMA24
B13: ติ่มซำ รองท้อง (ทอด) | D13: Nov
D14: Dec

Sheet Drop down list สาเหตุที่หยุด
A1: สาเหตุ | B1: มีConceptจากMktของCPRAMมาให้แต่เสนอConceptแล้วไม่ผ่าน | C1: มีConceptจากลูกค้ามาให้แต่เสนอConceptแล้วไม่ผ่าน | D1: ไม่มีConceptแต่เสนอสินค้าแล้วไม่ผ่าน | E1: ไม่ผ่านในขั้นตอนScreenTest | F1: Merหรือลูกค้าขอยกเลิก | G1: CPRAMขอยกเลิก | H1: อื่นๆ
A2: มีConceptจากMktของCPRAMมาให้แต่เสนอConceptแล้วไม่ผ่าน | B2: 1.1 เพราะสินค้าไม่ตรง Concept ที่ Mer หรือ ลูกค้า อยากได้ | C2: 2.1 เพราะสินค้าไม่ตรง Concept ที่ Mer หรือ ลูกค้า อยากได้ | D2: - | E2: 4.1 ต้นทุนวัตถุดิบไม่ผ่าน | F2: 5.1 เพราะราคา RM สูง ทำให้ราคาขายสูง | G2: 6.1 โรงงานติดปัญหาด้านแรงงานในการผลิต | H2: 7.1 อายุสินค้าไม่ได้ตามความต้องการของลูกค้า (sensory/micro)
A3: มีConceptจากลูกค้ามาให้แต่เสนอConceptแล้วไม่ผ่าน | B3: 1.2 เพราะสินค้าไม่เหมือน BM | C3: 2.2 เพราะสินค้าไม่เหมือน BM | E3: 4.2 ต้นทุนแรงงานไม่ผ่าน | F3: 5.2 เพราะเลื่อนขาย ราคาขายปลีกสูง (ช่วงโควิด) | G3: 6.2 โรงงานติดปัญหาด้านกระบวนการผลิตซับซ้อน | H3: 7.2 Hold เพราะสถานการณ์ Covid
A4: ไม่มีConceptแต่เสนอสินค้าแล้วไม่ผ่าน | B4: 1.3 เพราะSurvey ลูกค้าแล้วไม่ผ่าน, ไม่น่าสนใจ | C4: 2.3 ใกล้เคียงกับสินค้าที่จำหน่าย | E4: 4.3 ต้นทุน packaging ไม่ผ่าน | F4: 5.3 เพราะชิมเทียบ Control แล้ว ไม่ต้องการ IMP ระหว่าง Sensory Test | G4: 6.3 โรงงานติดปัญหาด้าน Capacity เครื่องจักร | H4: 7.3 สินค้าเพื่อจัดแสดงสินค้างาน Event ต่างๆ
A5: ไม่ผ่านในขั้นตอนScreenTest | B5: 1.4 เพราะ Mer แจ้งว่า Market Share น้อยเกินไป | E5: 4.4 วัตถุดิบ supply ไม่เพียงพอ | F5: 5.4 เพราะเปลี่ยน Concept ใหม่ | G5: 6.4 ติดข้อกำหนดโรงงาน เช่น ข้อกำหนดส่งออก GMP HACCP | H5: 7.4 ทำส่งซีพีแรมลาดกะบัง ไปประกอบเป็น FG
A6: Merหรือลูกค้าขอยกเลิก | B6: 1.5 ใกล้เคียงกับสินค้าที่จำหน่าย | E6: 4.5 วัตถุดิบพบปัญหาคุณภาพ | F6: 5.5 เพราะ sensory test ไม่ผ่าน | G6: 6.5 เครื่องจักรที่มีในโรงงานยังไม่รองรับการผลิต | H6: 7.5 ย้ายการผลิตไปลาดกะบัง
A7: CPRAMขอยกเลิก | B7: 1.6 ราคาขายปลีกสูงเกินไป ไม่สามารถจำหน่ายได้ตามต้นทุน | E7: 4.6 Mer/ลูกค้าขอยกเลิกขาย | F7: 5.6 เพราะไม่สามารถหาสาขาที่จะจำหน่ายได้ | G7: 6.6 ติดต้นทุน | H7: 7.6 ทางเมอร์มีเปลี่ยนโครงสร้างใหม่ จึงมีการปรับแผนสินค้าใหม่ด้วย
A8: อื่นๆ | F8: 5.7 เพราะไม่ผ่านวง Food Committee | H8: 7.7 เมอร์แจ้งว่า supplier อีกรายมีสินค้าลักษณะเดียวกัน จึงไม่อยากให้ซ้ำซ้อนกัน
F9: 5.8 เพราะจากการสำรวจผู้บริโภคยอมรับลักษณะปรากฏหรือรสชาติเดิม | H9: 7.8 โรงงานไม่ผ่านเกณฑ์ข้อกำหนด Sainsburry
A13: **เทคนิค คือ สาเหตุ ต้องห้ามใช้ตัวเลข ห้ามเว้นวรรค ห้ามใช้สัญลักษณ์ เช่น วงเล็บ ขีดกลาง

Sheet สาเหตุหยุด"ตามแผน"Yearlyของเก่า
A1: เหตุผลที่หยุดพัฒนา "ตามแผน" | B1: PMA02 | P1: PMA08 | AD1: PMA22 ข้าวเหนียว | AR1: PMA24 | BF1: PMA16 | BT1: PMA19 ข้าวปั้น | CH1: PMA19 chilled | CV1: PMA19 โครงการพิเศษ | DJ1: PMA22 ข้าว Chilled | DX1: PMA22 โครงการพิเศษ | EL1: PMA20 ข้าวFrozen | EZ1: PMA20 เกี๊ยว | FN1: PMA20 ทอด | GB1: PMA06 ทอด | GP1: PMA06 โครงการพิเศษ | HD1: PMA76 โครงการพิเศษ | HR1: non 7-11 โครงการพิเศษ | IF1: ติ่มซำ non-7 ในประเทศ | IT1: ส่งออก โครงการพิเศษ | JH1: ส่่งออก ทีมข้าวFrozen | JV1: ติ่มซำส่งออก | KJ1: Snack ส่งออก | KX1: Total
B2: Jan | C2: Feb | D2: Mar | E2: Apr | F2: May | G2: Jun | H2: Jul | I2: Aug | J2: Sep | K2: Oct | L2: Nov | M2: Dec | N2: Total | O2: % | P2: Jan | Q2: Feb | R2: Mar | S2: Apr | T2: May | U2: Jun | V2: Jul | W2: Aug | X2: Sep | Y2: Oct | Z2: Nov | AA2: Dec | AB2: Total | AC2: % | AD2: Jan | AE2: Feb | AF2: Mar | AG2: Apr | AH2: May | AI2: Jun | AJ2: Jul | AK2: Aug | AL2: Sep | AM2: Oct | AN2: Nov | AO2: Dec | AP2: Total | AQ2: % | AR2: Jan | AS2: Feb | AT2: Mar | AU2: Apr | AV2: May | AW2: Jun | AX2: Jul | AY2: Aug | AZ2: Sep | BA2: Oct | BB2: Nov | BC2: Dec | BD2: Total | BE2: % | BF2: Jan | BG2: Feb | BH2: Mar | BI2: Apr | BJ2: May | BK2: Jun | BL2: Jul | BM2: Aug | BN2: Sep | BO2: Oct | BP2: Nov | BQ2: Dec | BR2: Total | BS2: % | BT2: Jan | BU2: Feb | BV2: Mar | BW2: Apr | BX2: May | BY2: Jun | BZ2: Jul | CA2: Aug | CB2: Sep | CC2: Oct | CD2: Nov | CE2: Dec | CF2: Total | CG2: % | CH2: Jan | CI2: Feb | CJ2: Mar | CK2: Apr | CL2: May | CM2: Jun | CN2: Jul | CO2: Aug | CP2: Sep | CQ2: Oct | CR2: Nov | CS2: Dec | CT2: Total | CU2: % | CV2: Jan | CW2: Feb | CX2: Mar | CY2: Apr | CZ2: May | DA2: Jun | DB2: Jul | DC2: Aug | DD2: Sep | DE2: Oct | DF2: Nov | DG2: Dec | DH2: Total | DI2: % | DJ2: Jan | DK2: Feb | DL2: Mar | DM2: Apr | DN2: May | DO2: Jun | DP2: Jul | DQ2: Aug | DR2: Sep | DS2: Oct | DT2: Nov | DU2: Dec | DV2: Total | DW2: % | DX2: Jan | DY2: Feb | DZ2: Mar | EA2: Apr | EB2: May | EC2: Jun | ED2: Jul | EE2: Aug | EF2: Sep | EG2: Oct | EH2: Nov | EI2: Dec | EJ2: Total | EK2: % | EL2: Jan | EM2: Feb | EN2: Mar | EO2: Apr | EP2: May | EQ2: Jun | ER2: Jul | ES2: Aug | ET2: Sep | EU2: Oct | EV2: Nov | EW2: Dec | EX2: Total | EY2: % | EZ2: Jan | FA2: Feb | FB2: Mar | FC2: Apr | FD2: May | FE2: Jun | FF2: Jul | FG2: Aug | FH2: Sep | FI2: Oct | FJ2: Nov | FK2: Dec | FL2: Total | FM2: % | FN2: Jan | FO2: Feb | FP2: Mar | FQ2: Apr | FR2: May | FS2: Jun | FT2: Jul | FU2: Aug | FV2: Sep | FW2: Oct | FX2: Nov | FY2: Dec | FZ2: Total | GA2: % | GB2: Jan | GC2: Feb | GD2: Mar | GE2: Apr | GF2: May | GG2: Jun | GH2: Jul | GI2: Aug | GJ2: Sep | GK2: Oct | GL2: Nov | GM2: Dec | GN2: Total | GO2: % | GP2: Jan | GQ2: Feb | GR2: Mar | GS2: Apr | GT2: May | GU2: Jun | GV2: Jul | GW2: Aug | GX2: Sep | GY2: Oct | GZ2: Nov | HA2: Dec | HB2: Total | HC2: % | HD2: Jan | HE2: Feb | HF2: Mar | HG2: Apr | HH2: May | HI2: Jun | HJ2: Jul | HK2: Aug | HL2: Sep | HM2: Oct | HN2: Nov | HO2: Dec | HP2: Total | HQ2: % | HR2: Jan | HS2: Feb | HT2: Mar | HU2: Apr | HV2: May | HW2: Jun | HX2: Jul | HY2: Aug | HZ2: Sep | IA2: Oct | IB2: Nov | IC2: Dec | ID2: Total | IE2: % | IF2: Jan | IG2: Feb | IH2: Mar | II2: Apr | IJ2: May | IK2: Jun | IL2: Jul | IM2: Aug | IN2: Sep | IO2: Oct | IP2: Nov | IQ2: Dec | IR2: Total | IS2: % | IT2: Jan | IU2: Feb | IV2: Mar | IW2: Apr | IX2: May | IY2: Jun | IZ2: Jul | JA2: Aug | JB2: Sep | JC2: Oct | JD2: Nov | JE2: Dec | JF2: Total | JG2: % | JH2: Jan | JI2: Feb | JJ2: Mar | JK2: Apr | JL2: May | JM2: Jun | JN2: Jul | JO2: Aug | JP2: Sep | JQ2: Oct | JR2: Nov | JS2: Dec | JT2: Total | JU2: % | JV2: Jan | JW2: Feb | JX2: Mar | JY2: Apr | JZ2: May | KA2: Jun | KB2: Jul | KC2: Aug | KD2: Sep | KE2: Oct | KF2: Nov | KG2: Dec | KH2: Total | KI2: % | KJ2: Jan | KK2: Feb | KL2: Mar | KM2: Apr | KN2: May | KO2: Jun | KP2: Jul | KQ2: Aug | KR2: Sep | KS2: Oct | KT2: Nov | KU2: Dec | KV2: Total | KW2: % | KX2: SKU | KY2: %
A3: 1.มี Concept จาก Mkt CPRAM มาให้ แต่เสนอ Concept แล้วไม่ผ่าน | N3: =SUM(B3:M3) | O3: =N3/N$45% | AB3: =SUM(P3:AA3) | AC3: =AB3/AB$45% | AP3: =SUM(AD3:AO3) | AQ3: =AP3/AP$45% | BD3: =SUM(AR3:BC3) | BE3: =BD3/BD$45% | BR3: =SUM(BF3:BQ3) | BS3: =BR3/BR$45% | CF3: =SUM(BT3:CE3) | CG3: =CF3/CF$45% | CT3: =SUM(CH3:CS3) | CU3: =CT3/CT$45% | DH3: =SUM(CV3:DG3) | DI3: =DH3/DH$45% | DV3: =SUM(DJ3:DU3) | DW3: =DV3/DV$45% | EJ3: =SUM(DX3:EI3) | EK3: =EJ3/EJ$45% | EX3: =SUM(EL3:EW3) | EY3: =EX3/EX$45% | FL3: =SUM(EZ3:FK3) | FM3: =FL3/FL$45% | FZ3: =SUM(FN3:FY3) | GA3: =FZ3/FZ$45% | GN3: =SUM(GB3:GM3) | GO3: =GN3/GN$45% | HB3: =SUM(GP3:HA3) | HC3: =HB3/HB$45% | HP3: =SUM(HD3:HO3) | HQ3: =HP3/HP$45% | ID3: =SUM(HR3:IC3) | IE3: =ID3/ID$45% | IR3: =SUM(IF3:IQ3) | IS3: =IR3/IR$45% | JF3: =SUM(IT3:JE3) | JG3: =JF3/JF$45% | JT3: =SUM(JH3:JS3) | JU3: =JT3/JT$45% | KH3: =SUM(JV3:KG3) | KI3: =KH3/KH$45% | KT3: 0 | KV3: =SUM(KJ3:KU3) | KW3: =KV3/KV$45% | KX3: =N3+AB3+AP3+BD3+BR3+CF3+CT3+DH3+DV3+EJ3+EX3+FZ3+GN3+HB3+HP3+ID3+IR3+JF3+KH3+KV3+JT3 | KY3: =KX3/KX$45%
A4: 1.1 เพราะสินค้าไม่ตรง Concept ที่ Mer หรือ ลูกค้า อยากได้ | N4: =SUM(B4:M4) | AB4: =SUM(P4:AA4) | AP4: =SUM(AD4:AO4) | BD4: =SUM(AR4:BC4) | BR4: =SUM(BF4:BQ4) | CF4: =SUM(BT4:CE4) | CT4: =SUM(CH4:CS4) | DH4: =SUM(CV4:DG4) | DV4: =SUM(DJ4:DU4) | EJ4: =SUM(DX4:EI4) | EX4: =SUM(EL4:EW4) | FL4: =SUM(EZ4:FK4) | FZ4: =SUM(FN4:FY4) | GN4: =SUM(GB4:GM4) | HB4: =SUM(GP4:HA4) | HP4: =SUM(HD4:HO4) | ID4: =SUM(HR4:IC4) | IR4: =SUM(IF4:IQ4) | JF4: =SUM(IT4:JE4) | JT4: =SUM(JH4:JS4) | KH4: =SUM(JV4:KG4) | KV4: =SUM(KJ4:KU4)
A5: 1.2 เพราะสินค้าไม่เหมือน BM | N5: =SUM(B5:M5) | AB5: =SUM(P5:AA5) | AP5: =SUM(AD5:AO5) | BD5: =SUM(AR5:BC5) | BR5: =SUM(BF5:BQ5) | CF5: =SUM(BT5:CE5) | CT5: =SUM(CH5:CS5) | DH5: =SUM(CV5:DG5) | DV5: =SUM(DJ5:DU5) | EJ5: =SUM(DX5:EI5) | EX5: =SUM(EL5:EW5) | FL5: =SUM(EZ5:FK5) | FZ5: =SUM(FN5:FY5) | GN5: =SUM(GB5:GM5) | HB5: =SUM(GP5:HA5) | HP5: =SUM(HD5:HO5) | ID5: =SUM(HR5:IC5) | IR5: =SUM(IF5:IQ5) | JF5: =SUM(IT5:JE5) | JT5: =SUM(JH5:JS5) | KH5: =SUM(JV5:KG5) | KV5: =SUM(KJ5:KU5)
A6: 1.3 เพราะSurvey ลูกค้าแล้วไม่ผ่าน, ไม่น่าสนใจ | N6: =SUM(B6:M6) | AB6: =SUM(P6:AA6) | AP6: =SUM(AD6:AO6) | BD6: =SUM(AR6:BC6) | BR6: =SUM(BF6:BQ6) | CF6: =SUM(BT6:CE6) | CT6: =SUM(CH6:CS6) | DH6: =SUM(CV6:DG6) | DV6: =SUM(DJ6:DU6) | EJ6: =SUM(DX6:EI6) | EX6: =SUM(EL6:EW6) | FL6: =SUM(EZ6:FK6) | FZ6: =SUM(FN6:FY6) | GN6: =SUM(GB6:GM6) | HB6: =SUM(GP6:HA6) | HP6: =SUM(HD6:HO6) | ID6: =SUM(HR6:IC6) | IR6: =SUM(IF6:IQ6) | JF6: =SUM(IT6:JE6) | JT6: =SUM(JH6:JS6) | KH6: =SUM(JV6:KG6) | KV6: =SUM(KJ6:KU6)
A7: 1.4 เพราะ Mer แจ้งว่า Market Share น้อยเกินไป | N7: =SUM(B7:M7) | AB7: =SUM(P7:AA7) | AP7: =SUM(AD7:AO7) | BD7: =SUM(AR7:BC7) | BR7: =SUM(BF7:BQ7) | CF7: =SUM(BT7:CE7) | CT7: =SUM(CH7:CS7) | DH7: =SUM(CV7:DG7) | DV7: =SUM(DJ7:DU7) | EJ7: =SUM(DX7:EI7) | EX7: =SUM(EL7:EW7) | FL7: =SUM(EZ7:FK7) | FZ7: =SUM(FN7:FY7) | GN7: =SUM(GB7:GM7) | HB7: =SUM(GP7:HA7) | HP7: =SUM(HD7:HO7) | ID7: =SUM(HR7:IC7) | IR7: =SUM(IF7:IQ7) | JF7: =SUM(IT7:JE7) | JT7: =SUM(JH7:JS7) | KH7: =SUM(JV7:KG7) | KV7: =SUM(KJ7:KU7)
A8: 1.5 ใกล้เคียงกับสินค้าที่จำหน่าย | N8: =SUM(B8:M8) | AB8: =SUM(P8:AA8) | AP8: =SUM(AD8:AO8) | BD8: =SUM(AR8:BC8) | BR8: =SUM(BF8:BQ8) | CF8: =SUM(BT8:CE8) | CT8: =SUM(CH8:CS8) | DH8: =SUM(CV8:DG8) | DV8: =SUM(DJ8:DU8) | EJ8: =SUM(DX8:EI8) | EX8: =SUM(EL8:EW8) | FL8: =SUM(EZ8:FK8) | FZ8: =SUM(FN8:FY8) | GN8: =SUM(GB8:GM8) | HB8: =SUM(GP8:HA8) | HP8: =SUM(HD8:HO8) | ID8: =SUM(HR8:IC8) | IR8: =SUM(IF8:IQ8) | JF8: =SUM(IT8:JE8) | JT8: =SUM(JH8:JS8) | KH8: =SUM(JV8:KG8) | KV8: =SUM(KJ8:KU8)
A9: 1.6 ราคาขายปลีกสูงเกินไป ไม่สามารถจำหน่ายได้ตามต้นทุน | N9: =SUM(B9:M9) | AB9: =SUM(P9:AA9) | AP9: =SUM(AD9:AO9) | BD9: =SUM(AR9:BC9) | BR9: =SUM(BF9:BQ9) | CF9: =SUM(BT9:CE9) | CT9: =SUM(CH9:CS9) | DH9: =SUM(CV9:DG9) | DV9: =SUM(DJ9:DU9) | EJ9: =SUM(DX9:EI9) | EX9: =SUM(EL9:EW9) | FL9: =SUM(EZ9:FK9) | FZ9: =SUM(FN9:FY9) | GN9: =SUM(GB9:GM9) | HB9: =SUM(GP9:HA9) | HP9: =SUM(HD9:HO9) | ID9: =SUM(HR9:IC9) | IR9: =SUM(IF9:IQ9) | JF9: =SUM(IT9:JE9) | JT9: =SUM(JH9:JS9) | KH9: =SUM(JV9:KG9) | KV9: =SUM(KJ9:KU9)
A10: 2.มี Concept จากลูกค้ามาให้ แต่เสนอ Concept แล้วไม่ผ่าน | N10: =SUM(B10:M10) | O10: =N10/N$45% | AB10: =SUM(P10:AA10) | AC10: =AB10/AB$45% | AP10: =SUM(AD10:AO10) | AQ10: =AP10/AP$45% | BD10: =SUM(AR10:BC10) | BE10: =BD10/BD$45% | BR10: =SUM(BF10:BQ10) | BS10: =BR10/BR$45% | CF10: =SUM(BT10:CE10) | CG10: =CF10/CF$45% | CT10: =SUM(CH10:CS10) | CU10: =CT10/CT$45% | DH10: =SUM(CV10:DG10) | DI10: =DH10/DH$45% | DV10: =SUM(DJ10:DU10) | DW10: =DV10/DV$45% | EJ10: =SUM(DX10:EI10) | EK10: =EJ10/EJ$45% | EX10: =SUM(EL10:EW10) | EY10: =EX10/EX$45% | FL10: =SUM(EZ10:FK10) | FM10: =FL10/FL$45% | FZ10: =SUM(FN10:FY10) | GA10: =FZ10/FZ$45% | GN10: =SUM(GB10:GM10) | GO10: =GN10/GN$45% | HB10: =SUM(GP10:HA10) | HC10: =HB10/HB$45% | HP10: =SUM(HD10:HO10) | HQ10: =HP10/HP$45% | ID10: =SUM(HR10:IC10) | IE10: =ID10/ID$45% | IR10: =SUM(IF10:IQ10) | IS10: =IR10/IR$45% | JF10: =SUM(IT10:JE10) | JG10: =JF10/JF$45% | JT10: =SUM(JH10:JS10) | JU10: =JT10/JT$45% | KH10: =SUM(JV10:KG10) | KI10: =KH10/KH$45% | KV10: =SUM(KJ10:KU10) | KW10: =KV10/KV$45% | KX10: =N10+AB10+AP10+BD10+BR10+CF10+CT10+DH10+DV10+EJ10+EX10+FZ10+GN10+HB10+HP10+ID10+IR10+JF10+KH10+KV10+JT10 | KY10: =KX10/KX$45%
A11: 2.1 เพราะสินค้าไม่ตรง Concept ที่ Mer หรือ ลูกค้า อยากได้ | N11: =SUM(B11:M11) | AB11: =SUM(P11:AA11) | AP11: =SUM(AD11:AO11) | BD11: =SUM(AR11:BC11) | BR11: =SUM(BF11:BQ11) | CF11: =SUM(BT11:CE11) | CT11: =SUM(CH11:CS11) | DH11: =SUM(CV11:DG11) | DV11: =SUM(DJ11:DU11) | EJ11: =SUM(DX11:EI11) | EX11: =SUM(EL11:EW11) | FL11: =SUM(EZ11:FK11) | FZ11: =SUM(FN11:FY11) | GN11: =SUM(GB11:GM11) | HB11: =SUM(GP11:HA11) | HP11: =SUM(HD11:HO11) | ID11: =SUM(HR11:IC11) | IR11: =SUM(IF11:IQ11) | JF11: =SUM(IT11:JE11) | JT11: =SUM(JH11:JS11) | KH11: =SUM(JV11:KG11) | KV11: =SUM(KJ11:KU11)
A12: 2.2 เพราะสินค้าไม่เหมือน BM | N12: =SUM(B12:M12) | AB12: =SUM(P12:AA12) | AP12: =SUM(AD12:AO12) | BD12: =SUM(AR12:BC12) | BR12: =SUM(BF12:BQ12) | CF12: =SUM(BT12:CE12) | CT12: =SUM(CH12:CS12) | DH12: =SUM(CV12:DG12) | DV12: =SUM(DJ12:DU12) | EJ12: =SUM(DX12:EI12) | EX12: =SUM(EL12:EW12) | FL12: =SUM(EZ12:FK12) | FZ12: =SUM(FN12:FY12) | GN12: =SUM(GB12:GM12) | HB12: =SUM(GP12:HA12) | HP12: =SUM(HD12:HO12) | ID12: =SUM(HR12:IC12) | IR12: =SUM(IF12:IQ12) | JF12: =SUM(IT12:JE12) | JT12: =SUM(JH12:JS12) | KH12: =SUM(JV12:KG12) | KV12: =SUM(KJ12:KU12)
A13: 2.3 ใกล้เคียงกับสินค้าที่จำหน่าย | N13: =SUM(B13:M13) | AB13: =SUM(P13:AA13) | AP13: =SUM(AD13:AO13) | BD13: =SUM(AR13:BC13) | BR13: =SUM(BF13:BQ13) | CF13: =SUM(BT13:CE13) | CT13: =SUM(CH13:CS13) | DH13: =SUM(CV13:DG13) | DV13: =SUM(DJ13:DU13) | EJ13: =SUM(DX13:EI13) | EX13: =SUM(EL13:EW13) | FL13: =SUM(EZ13:FK13) | FZ13: =SUM(FN13:FY13) | GN13: =SUM(GB13:GM13) | HB13: =SUM(GP13:HA13) | HP13: =SUM(HD13:HO13) | ID13: =SUM(HR13:IC13) | IR13: =SUM(IF13:IQ13) | JF13: =SUM(IT13:JE13) | JT13: =SUM(JH13:JS13) | KH13: =SUM(JV13:KG13) | KV13: =SUM(KJ13:KU13)
A14: 2.4 ราคาขายปลีกสูงเกินไป ไม่สามารถจำหน่ายได้ตามต้นทุน | N14: =SUM(B14:M14) | AB14: =SUM(P14:AA14) | AP14: =SUM(AD14:AO14) | BD14: =SUM(AR14:BC14) | BR14: =SUM(BF14:BQ14) | CF14: =SUM(BT14:CE14) | CT14: =SUM(CH14:CS14) | DH14: =SUM(CV14:DG14) | DV14: =SUM(DJ14:DU14) | EJ14: =SUM(DX14:EI14) | EX14: =SUM(EL14:EW14) | FL14: =SUM(EZ14:FK14) | FZ14: =SUM(FN14:FY14) | GN14: =SUM(GB14:GM14) | HB14: =SUM(GP14:HA14) | HP14: =SUM(HD14:HO14) | ID14: =SUM(HR14:IC14) | IR14: =SUM(IF14:IQ14) | JF14: =SUM(IT14:JE14) | JT14: =SUM(JH14:JS14) | KH14: =SUM(JV14:KG14) | KV14: =SUM(KJ14:KU14)
A15: 3.ไม่มี Concept แต่เสนอสินค้าแล้วไม่ผ่าน | N15: =SUM(B15:M15) | O15: =N15/N$45% | AB15: =SUM(P15:AA15) | AC15: =AB15/AB$45% | AP15: =SUM(AD15:AO15) | AQ15: =AP15/AP$45% | BD15: =SUM(AR15:BC15) | BE15: =BD15/BD$45% | BR15: =SUM(BF15:BQ15) | BS15: =BR15/BR$45% | CF15: =SUM(BT15:CE15) | CG15: =CF15/CF$45% | CT15: =SUM(CH15:CS15) | CU15: =CT15/CT$45% | DH15: =SUM(CV15:DG15) | DI15: =DH15/DH$45% | DV15: =SUM(DJ15:DU15) | DW15: =DV15/DV$45% | EJ15: =SUM(DX15:EI15) | EK15: =EJ15/EJ$45% | EX15: =SUM(EL15:EW15) | EY15: =EX15/EX$45% | FL15: =SUM(EZ15:FK15) | FM15: =FL15/FL$45% | FZ15: =SUM(FN15:FY15) | GA15: =FZ15/FZ$45% | GN15: =SUM(GB15:GM15) | GO15: =GN15/GN$45% | HB15: =SUM(GP15:HA15) | HC15: =HB15/HB$45% | HP15: =SUM(HD15:HO15) | HQ15: =HP15/HP$45% | ID15: =SUM(HR15:IC15) | IE15: =ID15/ID$45% | IR15: =SUM(IF15:IQ15) | IS15: =IR15/IR$45% | JF15: =SUM(IT15:JE15) | JG15: =JF15/JF$45% | JT15: =SUM(JH15:JS15) | JU15: =JT15/JT$45% | KH15: =SUM(JV15:KG15) | KI15: =KH15/KH$45% | KV15: =SUM(KJ15:KU15) | KW15: =KV15/KV$45% | KX15: =N15+AB15+AP15+BD15+BR15+CF15+CT15+DH15+DV15+EJ15+EX15+FZ15+GN15+HB15+HP15+ID15+IR15+JF15+KH15+KV15+JT15 | KY15: =KX15/KX$45%
A16: 4.ไม่ผ่านในขั้นตอน Screen Test | N16: =SUM(B16:M16) | O16: =N16/N$45% | AB16: =SUM(P16:AA16) | AC16: =AB16/AB$45% | AP16: =SUM(AD16:AO16) | AQ16: =AP16/AP$45% | BD16: =SUM(AR16:BC16) | BE16: =BD16/BD$45% | BR16: =SUM(BF16:BQ16) | BS16: =BR16/BR$45% | CF16: =SUM(BT16:CE16) | CG16: =CF16/CF$45% | CT16: =SUM(CH16:CS16) | CU16: =CT16/CT$45% | DH16: =SUM(CV16:DG16) | DI16: =DH16/DH$45% | DV16: =SUM(DJ16:DU16) | DW16: =DV16/DV$45% | EJ16: =SUM(DX16:EI16) | EK16: =EJ16/EJ$45% | EX16: =SUM(EL16:EW16) | EY16: =EX16/EX$45% | FL16: =SUM(EZ16:FK16) | FM16: =FL16/FL$45% | FZ16: =SUM(FN16:FY16) | GA16: =FZ16/FZ$45% | GN16: =SUM(GB16:GM16) | GO16: =GN16/GN$45% | HB16: =SUM(GP16:HA16) | HC16: =HB16/HB$45% | HP16: =SUM(HD16:HO16) | HQ16: =HP16/HP$45% | ID16: =SUM(HR16:IC16) | IE16: =ID16/ID$45% | IR16: =SUM(IF16:IQ16) | IS16: =IR16/IR$45% | JF16: =SUM(IT16:JE16) | JG16: =JF16/JF$45% | JT16: =SUM(JH16:JS16) | JU16: =JT16/JT$45% | KH16: =SUM(JV16:KG16) | KI16: =KH16/KH$45% | KV16: =SUM(KJ16:KU16) | KW16: =KV16/KV$45% | KX16: =N16+AB16+AP16+BD16+BR16+CF16+CT16+DH16+DV16+EJ16+EX16+FZ16+GN16+HB16+HP16+ID16+IR16+JF16+KH16+KV16+JT16 | KY16: =KX16/KX$45%
A17: 4.1 ต้นทุนวัตถุดิบไม่ผ่าน | N17: =SUM(B17:M17) | AB17: =SUM(P17:AA17) | AP17: =SUM(AD17:AO17) | BD17: =SUM(AR17:BC17) | BR17: =SUM(BF17:BQ17) | CF17: =SUM(BT17:CE17) | CT17: =SUM(CH17:CS17) | DH17: =SUM(CV17:DG17) | DV17: =SUM(DJ17:DU17) | EJ17: =SUM(DX17:EI17) | EX17: =SUM(EL17:EW17) | FL17: =SUM(EZ17:FK17) | FZ17: =SUM(FN17:FY17) | GN17: =SUM(GB17:GM17) | HB17: =SUM(GP17:HA17) | HP17: =SUM(HD17:HO17) | ID17: =SUM(HR17:IC17) | IR17: =SUM(IF17:IQ17) | JF17: =SUM(IT17:JE17) | JT17: =SUM(JH17:JS17) | KH17: =SUM(JV17:KG17) | KV17: =SUM(KJ17:KU17)
A18: 4.2 ต้นทุนแรงงานไม่ผ่าน | N18: =SUM(B18:M18) | AB18: =SUM(P18:AA18) | AP18: =SUM(AD18:AO18) | BD18: =SUM(AR18:BC18) | BR18: =SUM(BF18:BQ18) | CF18: =SUM(BT18:CE18) | CT18: =SUM(CH18:CS18) | DH18: =SUM(CV18:DG18) | DV18: =SUM(DJ18:DU18) | EJ18: =SUM(DX18:EI18) | EX18: =SUM(EL18:EW18) | FL18: =SUM(EZ18:FK18) | FZ18: =SUM(FN18:FY18) | GN18: =SUM(GB18:GM18) | HB18: =SUM(GP18:HA18) | HP18: =SUM(HD18:HO18) | ID18: =SUM(HR18:IC18) | IR18: =SUM(IF18:IQ18) | JF18: =SUM(IT18:JE18) | JT18: =SUM(JH18:JS18) | KH18: =SUM(JV18:KG18) | KV18: =SUM(KJ18:KU18)
A19: 4.3 ต้นทุน packaging ไม่ผ่าน | N19: =SUM(B19:M19) | AB19: =SUM(P19:AA19) | AP19: =SUM(AD19:AO19) | BD19: =SUM(AR19:BC19) | BR19: =SUM(BF19:BQ19) | CF19: =SUM(BT19:CE19) | CT19: =SUM(CH19:CS19) | DH19: =SUM(CV19:DG19) | DV19: =SUM(DJ19:DU19) | EJ19: =SUM(DX19:EI19) | EX19: =SUM(EL19:EW19) | FL19: =SUM(EZ19:FK19) | FZ19: =SUM(FN19:FY19) | GN19: =SUM(GB19:GM19) | HB19: =SUM(GP19:HA19) | HP19: =SUM(HD19:HO19) | ID19: =SUM(HR19:IC19) | IR19: =SUM(IF19:IQ19) | JF19: =SUM(IT19:JE19) | JT19: =SUM(JH19:JS19) | KH19: =SUM(JV19:KG19) | KV19: =SUM(KJ19:KU19)
A20: 4.4 วัตถุดิบ supply ไม่เพียงพอ | N20: =SUM(B20:M20) | AB20: =SUM(P20:AA20) | AP20: =SUM(AD20:AO20) | BD20: =SUM(AR20:BC20) | BR20: =SUM(BF20:BQ20) | CF20: =SUM(BT20:CE20) | CT20: =SUM(CH20:CS20) | DH20: =SUM(CV20:DG20) | DV20: =SUM(DJ20:DU20) | EJ20: =SUM(DX20:EI20) | EX20: =SUM(EL20:EW20) | FL20: =SUM(EZ20:FK20) | FZ20: =SUM(FN20:FY20) | GN20: =SUM(GB20:GM20) | HB20: =SUM(GP20:HA20) | HP20: =SUM(HD20:HO20) | ID20: =SUM(HR20:IC20) | IR20: =SUM(IF20:IQ20) | JF20: =SUM(IT20:JE20) | JT20: =SUM(JH20:JS20) | KH20: =SUM(JV20:KG20) | KV20: =SUM(KJ20:KU20)
A21: 4.5 วัตถุดิบพบปัญหาคุณภาพ | N21: =SUM(B21:M21) | AB21: =SUM(P21:AA21) | AP21: =SUM(AD21:AO21) | BD21: =SUM(AR21:BC21) | BR21: =SUM(BF21:BQ21) | CF21: =SUM(BT21:CE21) | CT21: =SUM(CH21:CS21) | DH21: =SUM(CV21:DG21) | DV21: =SUM(DJ21:DU21) | EJ21: =SUM(DX21:EI21) | EX21: =SUM(EL21:EW21) | FL21: =SUM(EZ21:FK21) | FZ21: =SUM(FN21:FY21) | GN21: =SUM(GB21:GM21) | HB21: =SUM(GP21:HA21) | HP21: =SUM(HD21:HO21) | ID21: =SUM(HR21:IC21) | IR21: =SUM(IF21:IQ21) | JF21: =SUM(IT21:JE21) | JT21: =SUM(JH21:JS21) | KH21: =SUM(JV21:KG21) | KV21: =SUM(KJ21:KU21)
A22: 4.6 Mer/ลูกค้าขอยกเลิกขาย | N22: =SUM(B22:M22) | AB22: =SUM(P22:AA22) | AP22: =SUM(AD22:AO22) | BD22: =SUM(AR22:BC22) | BR22: =SUM(BF22:BQ22) | CF22: =SUM(BT22:CE22) | CT22: =SUM(CH22:CS22) | DH22: =SUM(CV22:DG22) | DV22: =SUM(DJ22:DU22) | EJ22: =SUM(DX22:EI22) | EX22: =SUM(EL22:EW22) | FL22: =SUM(EZ22:FK22) | FZ22: =SUM(FN22:FY22) | GN22: =SUM(GB22:GM22) | HB22: =SUM(GP22:HA22) | HP22: =SUM(HD22:HO22) | ID22: =SUM(HR22:IC22) | IR22: =SUM(IF22:IQ22) | JF22: =SUM(IT22:JE22) | JT22: =SUM(JH22:JS22) | KH22: =SUM(JV22:KG22) | KV22: =SUM(KJ22:KU22)
A23: 5.Mer/ลูกค้าขอยกเลิก | N23: =SUM(B23:M23) | O23: =N23/N$45% | AB23: =SUM(P23:AA23) | AC23: =AB23/AB$45% | AP23: =SUM(AD23:AO23) | AQ23: =AP23/AP$45% | BD23: =SUM(AR23:BC23) | BE23: =BD23/BD$45% | BR23: =SUM(BF23:BQ23) | BS23: =BR23/BR$45% | CF23: =SUM(BT23:CE23) | CG23: =CF23/CF$45% | CT23: =SUM(CH23:CS23) | CU23: =CT23/CT$45% | DH23: =SUM(CV23:DG23) | DI23: =DH23/DH$45% | DV23: =SUM(DJ23:DU23) | DW23: =DV23/DV$45% | EJ23: =SUM(DX23:EI23) | EK23: =EJ23/EJ$45% | EX23: =SUM(EL23:EW23) | EY23: =EX23/EX$45% | FL23: =SUM(EZ23:FK23) | FM23: =FL23/FL$45% | FZ23: =SUM(FN23:FY23) | GA23: =FZ23/FZ$45% | GN23: =SUM(GB23:GM23) | GO23: =GN23/GN$45% | HB23: =SUM(GP23:HA23) | HC23: =HB23/HB$45% | HP23: =SUM(HD23:HO23) | HQ23: =HP23/HP$45% | ID23: =SUM(HR23:IC23) | IE23: =ID23/ID$45% | IR23: =SUM(IF23:IQ23) | IS23: =IR23/IR$45% | JF23: =SUM(IT23:JE23) | JG23: =JF23/JF$45% | JT23: =SUM(JH23:JS23) | JU23: =JT23/JT$45% | KB23: 1 | KH23: =SUM(JV23:KG23) | KI23: =KH23/KH$45% | KP23: 1 | KV23: =SUM(KJ23:KU23) | KW23: =KV23/KV$45% | KX23: =N23+AB23+AP23+BD23+BR23+CF23+CT23+DH23+DV23+EJ23+EX23+FZ23+GN23+HB23+HP23+ID23+IR23+JF23+KH23+KV23+JT23 | KY23: =KX23/KX$45%
A24: 5.1 เพราะราคา RM สูง ทำให้ราคาขายสูง | N24: =SUM(B24:M24) | AB24: =SUM(P24:AA24) | AP24: =SUM(AD24:AO24) | BD24: =SUM(AR24:BC24) | BR24: =SUM(BF24:BQ24) | CF24: =SUM(BT24:CE24) | CT24: =SUM(CH24:CS24) | DH24: =SUM(CV24:DG24) | DV24: =SUM(DJ24:DU24) | EJ24: =SUM(DX24:EI24) | EX24: =SUM(EL24:EW24) | FL24: =SUM(EZ24:FK24) | FZ24: =SUM(FN24:FY24) | GN24: =SUM(GB24:GM24) | HB24: =SUM(GP24:HA24) | HP24: =SUM(HD24:HO24) | ID24: =SUM(HR24:IC24) | IR24: =SUM(IF24:IQ24) | JF24: =SUM(IT24:JE24) | JT24: =SUM(JH24:JS24) | KB24: 1 | KH24: =SUM(JV24:KG24) | KP24: 1 | KV24: =SUM(KJ24:KU24)
A25: 5.2 เพราะเลื่อนขาย ราคาขายปลีกสูง (ช่วงโควิด) | N25: =SUM(B25:M25) | AB25: =SUM(P25:AA25) | AP25: =SUM(AD25:AO25) | BD25: =SUM(AR25:BC25) | BR25: =SUM(BF25:BQ25) | CF25: =SUM(BT25:CE25) | CT25: =SUM(CH25:CS25) | DH25: =SUM(CV25:DG25) | DV25: =SUM(DJ25:DU25) | EJ25: =SUM(DX25:EI25) | EX25: =SUM(EL25:EW25) | FL25: =SUM(EZ25:FK25) | FZ25: =SUM(FN25:FY25) | GN25: =SUM(GB25:GM25) | HB25: =SUM(GP25:HA25) | HP25: =SUM(HD25:HO25) | ID25: =SUM(HR25:IC25) | IR25: =SUM(IF25:IQ25) | JF25: =SUM(IT25:JE25) | JT25: =SUM(JH25:JS25) | KH25: =SUM(JV25:KG25) | KV25: =SUM(KJ25:KU25)
A26: 5.3 เพราะชิมเทียบ Control แล้ว ไม่ต้องการ IMP ระหว่าง Sensory Test | N26: =SUM(B26:M26) | AB26: =SUM(P26:AA26) | AP26: =SUM(AD26:AO26) | BD26: =SUM(AR26:BC26) | BR26: =SUM(BF26:BQ26) | CF26: =SUM(BT26:CE26) | CT26: =SUM(CH26:CS26) | DH26: =SUM(CV26:DG26) | DV26: =SUM(DJ26:DU26) | EJ26: =SUM(DX26:EI26) | EX26: =SUM(EL26:EW26) | FL26: =SUM(EZ26:FK26) | FZ26: =SUM(FN26:FY26) | GN26: =SUM(GB26:GM26) | HB26: =SUM(GP26:HA26) | HP26: =SUM(HD26:HO26) | ID26: =SUM(HR26:IC26) | IR26: =SUM(IF26:IQ26) | JF26: =SUM(IT26:JE26) | JT26: =SUM(JH26:JS26) | KH26: =SUM(JV26:KG26) | KV26: =SUM(KJ26:KU26)
A27: 5.4 เพราะเปลี่ยน Concept ใหม่ | N27: =SUM(B27:M27) | AB27: =SUM(P27:AA27) | AP27: =SUM(AD27:AO27) | BD27: =SUM(AR27:BC27) | BR27: =SUM(BF27:BQ27) | CF27: =SUM(BT27:CE27) | CT27: =SUM(CH27:CS27) | DH27: =SUM(CV27:DG27) | DV27: =SUM(DJ27:DU27) | EJ27: =SUM(DX27:EI27) | EX27: =SUM(EL27:EW27) | FL27: =SUM(EZ27:FK27) | FZ27: =SUM(FN27:FY27) | GN27: =SUM(GB27:GM27) | HB27: =SUM(GP27:HA27) | HP27: =SUM(HD27:HO27) | ID27: =SUM(HR27:IC27) | IR27: =SUM(IF27:IQ27) | JF27: =SUM(IT27:JE27) | JT27: =SUM(JH27:JS27) | KH27: =SUM(JV27:KG27) | KV27: =SUM(KJ27:KU27)
A28: 5.5 เพราะ sensory test ไม่ผ่าน | N28: =SUM(B28:M28) | AB28: =SUM(P28:AA28) | AP28: =SUM(AD28:AO28) | BD28: =SUM(AR28:BC28) | BR28: =SUM(BF28:BQ28) | CF28: =SUM(BT28:CE28) | CT28: =SUM(CH28:CS28) | DH28: =SUM(CV28:DG28) | DV28: =SUM(DJ28:DU28) | EJ28: =SUM(DX28:EI28) | EX28: =SUM(EL28:EW28) | FL28: =SUM(EZ28:FK28) | FZ28: =SUM(FN28:FY28) | GN28: =SUM(GB28:GM28) | HB28: =SUM(GP28:HA28) | HP28: =SUM(HD28:HO28) | ID28: =SUM(HR28:IC28) | IR28: =SUM(IF28:IQ28) | JF28: =SUM(IT28:JE28) | JT28: =SUM(JH28:JS28) | KH28: =SUM(JV28:KG28) | KV28: =SUM(KJ28:KU28)
A29: 5.6 เพราะไม่สามารถหาสาขาที่จะจำหน่ายได้ | N29: =SUM(B29:M29) | AB29: =SUM(P29:AA29) | AP29: =SUM(AD29:AO29) | BD29: =SUM(AR29:BC29) | BR29: =SUM(BF29:BQ29) | CF29: =SUM(BT29:CE29) | CT29: =SUM(CH29:CS29) | DH29: =SUM(CV29:DG29) | DV29: =SUM(DJ29:DU29) | EJ29: =SUM(DX29:EI29) | EX29: =SUM(EL29:EW29) | FL29: =SUM(EZ29:FK29) | FZ29: =SUM(FN29:FY29) | GN29: =SUM(GB29:GM29) | HB29: =SUM(GP29:HA29) | HP29: =SUM(HD29:HO29) | ID29: =SUM(HR29:IC29) | IR29: =SUM(IF29:IQ29) | JF29: =SUM(IT29:JE29) | JT29: =SUM(JH29:JS29) | KH29: =SUM(JV29:KG29) | KV29: =SUM(KJ29:KU29)
A30: 5.7 เพราะไม่ผ่านวง Food Committee | N30: =SUM(B30:M30) | AB30: =SUM(P30:AA30) | AP30: =SUM(AD30:AO30) | BD30: =SUM(AR30:BC30) | BR30: =SUM(BF30:BQ30) | CF30: =SUM(BT30:CE30) | CT30: =SUM(CH30:CS30) | DH30: =SUM(CV30:DG30) | DV30: =SUM(DJ30:DU30) | EJ30: =SUM(DX30:EI30) | EX30: =SUM(EL30:EW30) | FL30: =SUM(EZ30:FK30) | FZ30: =SUM(FN30:FY30) | GN30: =SUM(GB30:GM30) | HB30: =SUM(GP30:HA30) | HP30: =SUM(HD30:HO30) | ID30: =SUM(HR30:IC30) | IR30: =SUM(IF30:IQ30) | JF30: =SUM(IT30:JE30) | JT30: =SUM(JH30:JS30) | KH30: =SUM(JV30:KG30) | KV30: =SUM(KJ30:KU30)
A31: 5.8 เพราะจากการสำรวจผู้บริโภคยอมรับลักษณะปรากฏหรือรสชาติเดิม | N31: =SUM(B31:M31) | AB31: =SUM(P31:AA31) | AP31: =SUM(AD31:AO31) | BD31: =SUM(AR31:BC31) | BR31: =SUM(BF31:BQ31) | CF31: =SUM(BT31:CE31) | CT31: =SUM(CH31:CS31) | DH31: =SUM(CV31:DG31) | DV31: =SUM(DJ31:DU31) | EJ31: =SUM(DX31:EI31) | EX31: =SUM(EL31:EW31) | FL31: =SUM(EZ31:FK31) | FZ31: =SUM(FN31:FY31) | GN31: =SUM(GB31:GM31) | HB31: =SUM(GP31:HA31) | HP31: =SUM(HD31:HO31) | ID31: =SUM(HR31:IC31) | IR31: =SUM(IF31:IQ31) | JF31: =SUM(IT31:JE31) | JT31: =SUM(JH31:JS31) | KH31: =SUM(JV31:KG31) | KV31: =SUM(KJ31:KU31)
A32: 6.CPRAM ขอยกเลิก | N32: =SUM(B32:M32) | O32: =N32/N$45% | AB32: =SUM(P32:AA32) | AC32: =AB32/AB$45% | AP32: =SUM(AD32:AO32) | AQ32: =AP32/AP$45% | BD32: =SUM(AR32:BC32) | BE32: =BD32/BD$45% | BR32: =SUM(BF32:BQ32) | BS32: =BR32/BR$45% | CF32: =SUM(BT32:CE32) | CG32: =CF32/CF$45% | CT32: =SUM(CH32:CS32) | CU32: =CT32/CT$45% | DH32: =SUM(CV32:DG32) | DI32: =DH32/DH$45% | DV32: =SUM(DJ32:DU32) | DW32: =DV32/DV$45% | EJ32: =SUM(DX32:EI32) | EK32: =EJ32/EJ$45% | EX32: =SUM(EL32:EW32) | EY32: =EX32/EX$45% | FL32: =SUM(EZ32:FK32) | FM32: =FL32/FL$45% | FZ32: =SUM(FN32:FY32) | GA32: =FZ32/FZ$45% | GN32: =SUM(GB32:GM32) | GO32: =GN32/GN$45% | HB32: =SUM(GP32:HA32) | HC32: =HB32/HB$45% | HP32: =SUM(HD32:HO32) | HQ32: =HP32/HP$45% | ID32: =SUM(HR32:IC32) | IE32: =ID32/ID$45% | IR32: =SUM(IF32:IQ32) | IS32: =IR32/IR$45% | JF32: =SUM(IT32:JE32) | JG32: =JF32/JF$45% | JT32: =SUM(JH32:JS32) | JU32: =JT32/JT$45% | KH32: =SUM(JV32:KG32) | KI32: =KH32/KH$45% | KV32: =SUM(KJ32:KU32) | KW32: =KV32/KV$45% | KX32: =N32+AB32+AP32+BD32+BR32+CF32+CT32+DH32+DV32+EJ32+EX32+FZ32+GN32+HB32+HP32+ID32+IR32+JF32+KH32+KV32+JT32 | KY32: =KX32/KX$45%
A33: 6.1 โรงงานติดปัญหาด้านแรงงานในการผลิต | N33: =SUM(B33:M33) | AB33: =SUM(P33:AA33) | AP33: =SUM(AD33:AO33) | BD33: =SUM(AR33:BC33) | BR33: =SUM(BF33:BQ33) | CF33: =SUM(BT33:CE33) | CT33: =SUM(CH33:CS33) | DH33: =SUM(CV33:DG33) | DV33: =SUM(DJ33:DU33) | EJ33: =SUM(DX33:EI33) | EX33: =SUM(EL33:EW33) | FL33: =SUM(EZ33:FK33) | FZ33: =SUM(FN33:FY33) | GN33: =SUM(GB33:GM33) | HB33: =SUM(GP33:HA33) | HP33: =SUM(HD33:HO33) | ID33: =SUM(HR33:IC33) | IR33: =SUM(IF33:IQ33) | JF33: =SUM(IT33:JE33) | JT33: =SUM(JH33:JS33) | KH33: =SUM(JV33:KG33) | KV33: =SUM(KJ33:KU33)
A34: 6.2 โรงงานติดปัญหาด้านกระบวนการผลิตซับซ้อน | N34: =SUM(B34:M34) | AB34: =SUM(P34:AA34) | AP34: =SUM(AD34:AO34) | BD34: =SUM(AR34:BC34) | BR34: =SUM(BF34:BQ34) | CF34: =SUM(BT34:CE34) | CT34: =SUM(CH34:CS34) | DH34: =SUM(CV34:DG34) | DV34: =SUM(DJ34:DU34) | EJ34: =SUM(DX34:EI34) | EX34: =SUM(EL34:EW34) | FL34: =SUM(EZ34:FK34) | FZ34: =SUM(FN34:FY34) | GN34: =SUM(GB34:GM34) | HB34: =SUM(GP34:HA34) | HP34: =SUM(HD34:HO34) | ID34: =SUM(HR34:IC34) | IR34: =SUM(IF34:IQ34) | JF34: =SUM(IT34:JE34) | JT34: =SUM(JH34:JS34) | KH34: =SUM(JV34:KG34) | KV34: =SUM(KJ34:KU34)
A35: 6.3 โรงงานติดปัญหาด้าน Capacity เครื่องจักร | N35: =SUM(B35:M35) | AB35: =SUM(P35:AA35) | AP35: =SUM(AD35:AO35) | BD35: =SUM(AR35:BC35) | BR35: =SUM(BF35:BQ35) | CF35: =SUM(BT35:CE35) | CT35: =SUM(CH35:CS35) | DH35: =SUM(CV35:DG35) | DV35: =SUM(DJ35:DU35) | EJ35: =SUM(DX35:EI35) | EX35: =SUM(EL35:EW35) | FL35: =SUM(EZ35:FK35) | FZ35: =SUM(FN35:FY35) | GN35: =SUM(GB35:GM35) | HB35: =SUM(GP35:HA35) | HP35: =SUM(HD35:HO35) | ID35: =SUM(HR35:IC35) | IR35: =SUM(IF35:IQ35) | JF35: =SUM(IT35:JE35) | JT35: =SUM(JH35:JS35) | KH35: =SUM(JV35:KG35) | KV35: =SUM(KJ35:KU35)
A36: 6.4 ติดข้อกำหนดโรงงาน เช่น ข้อกำหนดส่งออก GMP HACCP | N36: =SUM(B36:M36) | AB36: =SUM(P36:AA36) | AP36: =SUM(AD36:AO36) | BD36: =SUM(AR36:BC36) | BR36: =SUM(BF36:BQ36) | CF36: =SUM(BT36:CE36) | CT36: =SUM(CH36:CS36) | DH36: =SUM(CV36:DG36) | DV36: =SUM(DJ36:DU36) | EJ36: =SUM(DX36:EI36) | EX36: =SUM(EL36:EW36) | FL36: =SUM(EZ36:FK36) | FZ36: =SUM(FN36:FY36) | GN36: =SUM(GB36:GM36) | HB36: =SUM(GP36:HA36) | HP36: =SUM(HD36:HO36) | ID36: =SUM(HR36:IC36) | IR36: =SUM(IF36:IQ36) | JF36: =SUM(IT36:JE36) | JT36: =SUM(JH36:JS36) | KH36: =SUM(JV36:KG36) | KV36: =SUM(KJ36:KU36)
A37: 6.5 เครื่องจักรที่มีในโรงงานยังไม่รองรับการผลิต | N37: =SUM(B37:M37) | AB37: =SUM(P37:AA37) | AP37: =SUM(AD37:AO37) | BD37: =SUM(AR37:BC37) | BR37: =SUM(BF37:BQ37) | CF37: =SUM(BT37:CE37) | CT37: =SUM(CH37:CS37) | DH37: =SUM(CV37:DG37) | DV37: =SUM(DJ37:DU37) | EJ37: =SUM(DX37:EI37) | EX37: =SUM(EL37:EW37) | FL37: =SUM(EZ37:FK37) | FZ37: =SUM(FN37:FY37) | GN37: =SUM(GB37:GM37) | HB37: =SUM(GP37:HA37) | HP37: =SUM(HD37:HO37) | ID37: =SUM(HR37:IC37) | IR37: =SUM(IF37:IQ37) | JF37: =SUM(IT37:JE37) | JT37: =SUM(JH37:JS37) | KH37: =SUM(JV37:KG37) | KV37: =SUM(KJ37:KU37)
A38: 7.อื่นๆ | N38: =SUM(B38:M38) | O38: =N38/N$45% | AB38: =SUM(P38:AA38) | AC38: =AB38/AB$45% | AP38: =SUM(AD38:AO38) | AQ38: =AP38/AP$45% | BD38: =SUM(AR38:BC38) | BE38: =BD38/BD$45% | BR38: =SUM(BF38:BQ38) | BS38: =BR38/BR$45% | CF38: =SUM(BT38:CE38) | CG38: =CF38/CF$45% | CT38: =SUM(CH38:CS38) | CU38: =CT38/CT$45% | DH38: =SUM(CV38:DG38) | DI38: =DH38/DH$45% | DV38: =SUM(DJ38:DU38) | DW38: =DV38/DV$45% | EJ38: =SUM(DX38:EI38) | EK38: =EJ38/EJ$45% | EX38: =SUM(EL38:EW38) | EY38: =EX38/EX$45% | FL38: =SUM(EZ38:FK38) | FM38: =FL38/FL$45% | FZ38: =SUM(FN38:FY38) | GA38: =FZ38/FZ$45% | GN38: =SUM(GB38:GM38) | GO38: =GN38/GN$45% | HB38: =SUM(GP38:HA38) | HC38: =HB38/HB$45% | HP38: =SUM(HD38:HO38) | HQ38: =HP38/HP$45% | ID38: =SUM(HR38:IC38) | IE38: =ID38/ID$45% | IR38: =SUM(IF38:IQ38) | IS38: =IR38/IR$45% | JF38: =SUM(IT38:JE38) | JG38: =JF38/JF$45% | JT38: =SUM(JH38:JS38) | JU38: =JT38/JT$45% | KH38: =SUM(JV38:KG38) | KI38: =KH38/KH$45% | KV38: =SUM(KJ38:KU38) | KW38: =KV38/KV$45% | KX38: =N38+AB38+AP38+BD38+BR38+CF38+CT38+DH38+DV38+EJ38+EX38+FZ38+GN38+HB38+HP38+ID38+IR38+JF38+KH38+KV38+JT38 | KY38: =KX38/KX$45%
A39: 7.1 อายุสินค้าไม่ได้ตามความต้องการของลูกค้า (sensory/micro) | N39: =SUM(B39:M39) | AB39: =SUM(P39:AA39) | AP39: =SUM(AD39:AO39) | BD39: =SUM(AR39:BC39) | BR39: =SUM(BF39:BQ39) | CF39: =SUM(BT39:CE39) | CT39: =SUM(CH39:CS39) | DH39: =SUM(CV39:DG39) | DV39: =SUM(DJ39:DU39) | EJ39: =SUM(DX39:EI39) | EX39: =SUM(EL39:EW39) | FL39: =SUM(EZ39:FK39) | FZ39: =SUM(FN39:FY39) | GN39: =SUM(GB39:GM39) | HB39: =SUM(GP39:HA39) | HP39: =SUM(HD39:HO39) | ID39: =SUM(HR39:IC39) | IR39: =SUM(IF39:IQ39) | JF39: =SUM(IT39:JE39) | JT39: =SUM(JH39:JS39) | KH39: =SUM(JV39:KG39) | KV39: =SUM(KJ39:KU39)
A40: 7.2 Hold เพราะสถานการณ์ Covid | N40: =SUM(B40:M40) | AB40: =SUM(P40:AA40) | AP40: =SUM(AD40:AO40) | BD40: =SUM(AR40:BC40) | BR40: =SUM(BF40:BQ40) | CF40: =SUM(BT40:CE40) | CT40: =SUM(CH40:CS40) | DH40: =SUM(CV40:DG40) | DV40: =SUM(DJ40:DU40) | EJ40: =SUM(DX40:EI40) | EX40: =SUM(EL40:EW40) | FL40: =SUM(EZ40:FK40) | FZ40: =SUM(FN40:FY40) | GN40: =SUM(GB40:GM40) | HB40: =SUM(GP40:HA40) | HP40: =SUM(HD40:HO40) | ID40: =SUM(HR40:IC40) | IR40: =SUM(IF40:IQ40) | JF40: =SUM(IT40:JE40) | JT40: =SUM(JH40:JS40) | KH40: =SUM(JV40:KG40) | KV40: =SUM(KJ40:KU40)
...

Sheet สาเหตุหยุด"นอกแผน"Yearlyของเก่า
A1: เหตุผลที่หยุดพัฒนา "นอกแผน" | B1: PMA02 | P1: PMA08 | AD1: PMA22 ข้าวเหนียว | AR1: PMA24 | BF1: PMA16 | BT1: PMA19 ข้าวปั้น | CH1: PMA19 chilled | CV1: PMA19 โครงการพิเศษ | DJ1: PMA22 ข้าว Chilled | DX1: PMA22 โครงการพิเศษ | EL1: PMA20 ข้าวFrozen | EZ1: PMA20 เกี๊ยว | FN1: PMA20 ทอด | GB1: PMA06 ทอด | GP1: PMA06 โครงการพิเศษ | HD1: PMA76 โครงการพิเศษ | HR1: non 7-11 โครงการพิเศษ | IF1: ติ่มซำ non-7 ในประเทศ | IT1: ส่งออก โครงการพิเศษ | JH1: ส่่งออก ทีมข้าวFrozen | JV1: ติ่มซำส่งออก | KJ1: Snack ส่งออก | KX1: Total
B2: Jan | C2: Feb | D2: Mar | E2: Apr | F2: May | G2: Jun | H2: Jul | I2: Aug | J2: Sep | K2: Oct | L2: Nov | M2: Dec | N2: Total | O2: % | P2: Jan | Q2: Feb | R2: Mar | S2: Apr | T2: May | U2: Jun | V2: Jul | W2: Aug | X2: Sep | Y2: Oct | Z2: Nov | AA2: Dec | AB2: Total | AC2: % | AD2: Jan | AE2: Feb | AF2: Mar | AG2: Apr | AH2: May | AI2: Jun | AJ2: Jul | AK2: Aug | AL2: Sep | AM2: Oct | AN2: Nov | AO2: Dec | AP2: Total | AQ2: % | AR2: Jan | AS2: Feb | AT2: Mar | AU2: Apr | AV2: May | AW2: Jun | AX2: Jul | AY2: Aug | AZ2: Sep | BA2: Oct | BB2: Nov | BC2: Dec | BD2: Total | BE2: % | BF2: Jan | BG2: Feb | BH2: Mar | BI2: Apr | BJ2: May | BK2: Jun | BL2: Jul | BM2: Aug | BN2: Sep | BO2: Oct | BP2: Nov | BQ2: Dec | BR2: Total | BS2: % | BT2: Jan | BU2: Feb | BV2: Mar | BW2: Apr | BX2: May | BY2: Jun | BZ2: Jul | CA2: Aug | CB2: Sep | CC2: Oct | CD2: Nov | CE2: Dec | CF2: Total | CG2: % | CH2: Jan | CI2: Feb | CJ2: Mar | CK2: Apr | CL2: May | CM2: Jun | CN2: Jul | CO2: Aug | CP2: Sep | CQ2: Oct | CR2: Nov | CS2: Dec | CT2: Total | CU2: % | CV2: Jan | CW2: Feb | CX2: Mar | CY2: Apr | CZ2: May | DA2: Jun | DB2: Jul | DC2: Aug | DD2: Sep | DE2: Oct | DF2: Nov | DG2: Dec | DH2: Total | DI2: % | DJ2: Jan | DK2: Feb | DL2: Mar | DM2: Apr | DN2: May | DO2: Jun | DP2: Jul | DQ2: Aug | DR2: Sep | DS2: Oct | DT2: Nov | DU2: Dec | DV2: Total | DW2: % | DX2: Jan | DY2: Feb | DZ2: Mar | EA2: Apr | EB2: May | EC2: Jun | ED2: Jul | EE2: Aug | EF2: Sep | EG2: Oct | EH2: Nov | EI2: Dec | EJ2: Total | EK2: % | EL2: Jan | EM2: Feb | EN2: Mar | EO2: Apr | EP2: May | EQ2: Jun | ER2: Jul | ES2: Aug | ET2: Sep | EU2: Oct | EV2: Nov | EW2: Dec | EX2: Total | EY2: % | EZ2: Jan | FA2: Feb | FB2: Mar | FC2: Apr | FD2: May | FE2: Jun | FF2: Jul | FG2: Aug | FH2: Sep | FI2: Oct | FJ2: Nov | FK2: Dec | FL2: Total | FM2: % | FN2: Jan | FO2: Feb | FP2: Mar | FQ2: Apr | FR2: May | FS2: Jun | FT2: Jul | FU2: Aug | FV2: Sep | FW2: Oct | FX2: Nov | FY2: Dec | FZ2: Total | GA2: % | GB2: Jan | GC2: Feb | GD2: Mar | GE2: Apr | GF2: May | GG2: Jun | GH2: Jul | GI2: Aug | GJ2: Sep | GK2: Oct | GL2: Nov | GM2: Dec | GN2: Total | GO2: % | GP2: Jan | GQ2: Feb | GR2: Mar | GS2: Apr | GT2: May | GU2: Jun | GV2: Jul | GW2: Aug | GX2: Sep | GY2: Oct | GZ2: Nov | HA2: Dec | HB2: Total | HC2: % | HD2: Jan | HE2: Feb | HF2: Mar | HG2: Apr | HH2: May | HI2: Jun | HJ2: Jul | HK2: Aug | HL2: Sep | HM2: Oct | HN2: Nov | HO2: Dec | HP2: Total | HQ2: % | HR2: Jan | HS2: Feb | HT2: Mar | HU2: Apr | HV2: May | HW2: Jun | HX2: Jul | HY2: Aug | HZ2: Sep | IA2: Oct | IB2: Nov | IC2: Dec | ID2: Total | IE2: % | IF2: Jan | IG2: Feb | IH2: Mar | II2: Apr | IJ2: May | IK2: Jun | IL2: Jul | IM2: Aug | IN2: Sep | IO2: Oct | IP2: Nov | IQ2: Dec | IR2: Total | IS2: % | IT2: Jan | IU2: Feb | IV2: Mar | IW2: Apr | IX2: May | IY2: Jun | IZ2: Jul | JA2: Aug | JB2: Sep | JC2: Oct | JD2: Nov | JE2: Dec | JF2: Total | JG2: % | JH2: Jan | JI2: Feb | JJ2: Mar | JK2: Apr | JL2: May | JM2: Jun | JN2: Jul | JO2: Aug | JP2: Sep | JQ2: Oct | JR2: Nov | JS2: Dec | JT2: Total | JU2: % | JV2: Jan | JW2: Feb | JX2: Mar | JY2: Apr | JZ2: May | KA2: Jun | KB2: Jul | KC2: Aug | KD2: Sep | KE2: Oct | KF2: Nov | KG2: Dec | KH2: Total | KI2: % | KJ2: Jan | KK2: Feb | KL2: Mar | KM2: Apr | KN2: May | KO2: Jun | KP2: Jul | KQ2: Aug | KR2: Sep | KS2: Oct | KT2: Nov | KU2: Dec | KV2: Total | KW2: % | KX2: SKU | KY2: %
A3: 1.มี Concept จาก Mkt CPRAM มาให้ แต่เสนอ Concept แล้วไม่ผ่าน | N3: =SUM(B3:M3) | O3: =N3/N$46% | AB3: =SUM(P3:AA3) | AC3: =AB3/AB$46% | AP3: =SUM(AD3:AO3) | AQ3: =AP3/AP$46% | AS3: 1 | AU3: 1 | BD3: =SUM(AR3:BC3) | BE3: =BD3/BD$46% | BR3: =SUM(BF3:BQ3) | BS3: =BR3/BR$46% | CF3: =SUM(BT3:CE3) | CG3: =CF3/CF$46% | CT3: =SUM(CH3:CS3) | CU3: =CT3/CT$46% | DH3: =SUM(CV3:DG3) | DI3: =DH3/DH$46% | DV3: =SUM(DJ3:DU3) | DW3: =DV3/DV$46% | EJ3: =SUM(DX3:EI3) | EK3: =EJ3/EJ$46% | EN3: 1 | EO3: 4 | EP3: 6 | EQ3: 1 | ER3: 2 | EX3: =SUM(EL3:EW3) | EY3: =EX3/EX$46% | FL3: =SUM(EZ3:FK3) | FM3: =FL3/FL$46% | FZ3: =SUM(FN3:FY3) | GA3: =FZ3/FZ$46% | GN3: =SUM(GB3:GM3) | GO3: =GN3/GN$46% | GP3: 1 | HB3: =SUM(GP3:HA3) | HC3: =HB3/HB$46% | HP3: =SUM(HD3:HO3) | HQ3: =HP3/HP$46% | ID3: =SUM(HR3:IC3) | IE3: =ID3/ID$46% | IR3: =SUM(IF3:IQ3) | IS3: =IR3/IR$46% | JF3: =SUM(IT3:JE3) | JG3: =JF3/JF$46% | JT3: =SUM(JH3:JS3) | JU3: =JT3/JT$46% | KA3: 4 | KH3: =SUM(JV3:KG3) | KI3: =KH3/KH$46% | KV3: =SUM(KJ3:KU3) | KW3: =KV3/KV$46% | KX3: =N3+AB3+AP3+BD3+BR3+CF3+CT3+DH3+DV3+EJ3+EX3+FZ3+GN3+HB3+HP3+ID3+IR3+JF3+KH3+KV3+JT3 | KY3: =KX3/KX$46%
A4: 1.1 เพราะสินค้าไม่ตรง Concept ที่ Mer หรือ ลูกค้า อยากได้ | N4: =SUM(B4:M4) | AB4: =SUM(P4:AA4) | AP4: =SUM(AD4:AO4) | AS4: 1 | AU4: 1 | BD4: =SUM(AR4:BC4) | BR4: =SUM(BF4:BQ4) | CF4: =SUM(BT4:CE4) | CT4: =SUM(CH4:CS4) | DH4: =SUM(CV4:DG4) | DV4: =SUM(DJ4:DU4) | EJ4: =SUM(DX4:EI4) | EN4: 1 | EO4: 4 | EP4: 6 | EQ4: 1 | ER4: 1 | EX4: =SUM(EL4:EW4) | FL4: =SUM(EZ4:FK4) | FZ4: =SUM(FN4:FY4) | GN4: =SUM(GB4:GM4) | GP4: 1 | HB4: =SUM(GP4:HA4) | HP4: =SUM(HD4:HO4) | ID4: =SUM(HR4:IC4) | IR4: =SUM(IF4:IQ4) | JF4: =SUM(IT4:JE4) | JT4: =SUM(JH4:JS4) | KA4: 4 | KH4: =SUM(JV4:KG4) | KV4: =SUM(KJ4:KU4)
A5: 1.2 เพราะสินค้าไม่เหมือน BM | N5: =SUM(B5:M5) | AB5: =SUM(P5:AA5) | AP5: =SUM(AD5:AO5) | BD5: =SUM(AR5:BC5) | BR5: =SUM(BF5:BQ5) | CF5: =SUM(BT5:CE5) | CT5: =SUM(CH5:CS5) | DH5: =SUM(CV5:DG5) | DV5: =SUM(DJ5:DU5) | EJ5: =SUM(DX5:EI5) | EX5: =SUM(EL5:EW5) | FL5: =SUM(EZ5:FK5) | FZ5: =SUM(FN5:FY5) | GN5: =SUM(GB5:GM5) | HB5: =SUM(GP5:HA5) | HP5: =SUM(HD5:HO5) | ID5: =SUM(HR5:IC5) | IR5: =SUM(IF5:IQ5) | JF5: =SUM(IT5:JE5) | JT5: =SUM(JH5:JS5) | KH5: =SUM(JV5:KG5) | KV5: =SUM(KJ5:KU5)
A6: 1.3 เพราะSurvey ลูกค้าแล้วไม่ผ่าน, ไม่น่าสนใจ | N6: =SUM(B6:M6) | AB6: =SUM(P6:AA6) | AP6: =SUM(AD6:AO6) | BD6: =SUM(AR6:BC6) | BR6: =SUM(BF6:BQ6) | CF6: =SUM(BT6:CE6) | CT6: =SUM(CH6:CS6) | DH6: =SUM(CV6:DG6) | DV6: =SUM(DJ6:DU6) | EJ6: =SUM(DX6:EI6) | EX6: =SUM(EL6:EW6) | FL6: =SUM(EZ6:FK6) | FZ6: =SUM(FN6:FY6) | GN6: =SUM(GB6:GM6) | HB6: =SUM(GP6:HA6) | HP6: =SUM(HD6:HO6) | ID6: =SUM(HR6:IC6) | IR6: =SUM(IF6:IQ6) | JF6: =SUM(IT6:JE6) | JT6: =SUM(JH6:JS6) | KH6: =SUM(JV6:KG6) | KV6: =SUM(KJ6:KU6)
A7: 1.4 เพราะ Mer แจ้งว่า Market Share น้อยเกินไป | N7: =SUM(B7:M7) | AB7: =SUM(P7:AA7) | AP7: =SUM(AD7:AO7) | BD7: =SUM(AR7:BC7) | BR7: =SUM(BF7:BQ7) | CF7: =SUM(BT7:CE7) | CT7: =SUM(CH7:CS7) | DH7: =SUM(CV7:DG7) | DV7: =SUM(DJ7:DU7) | EJ7: =SUM(DX7:EI7) | EX7: =SUM(EL7:EW7) | FL7: =SUM(EZ7:FK7) | FZ7: =SUM(FN7:FY7) | GN7: =SUM(GB7:GM7) | HB7: =SUM(GP7:HA7) | HP7: =SUM(HD7:HO7) | ID7: =SUM(HR7:IC7) | IR7: =SUM(IF7:IQ7) | JF7: =SUM(IT7:JE7) | JT7: =SUM(JH7:JS7) | KH7: =SUM(JV7:KG7) | KV7: =SUM(KJ7:KU7)
A8: 1.5 ใกล้เคียงกับสินค้าที่จำหน่าย | N8: =SUM(B8:M8) | AB8: =SUM(P8:AA8) | AP8: =SUM(AD8:AO8) | BD8: =SUM(AR8:BC8) | BR8: =SUM(BF8:BQ8) | CF8: =SUM(BT8:CE8) | CT8: =SUM(CH8:CS8) | DH8: =SUM(CV8:DG8) | DV8: =SUM(DJ8:DU8) | EJ8: =SUM(DX8:EI8) | EX8: =SUM(EL8:EW8) | FL8: =SUM(EZ8:FK8) | FZ8: =SUM(FN8:FY8) | GN8: =SUM(GB8:GM8) | HB8: =SUM(GP8:HA8) | HP8: =SUM(HD8:HO8) | ID8: =SUM(HR8:IC8) | IR8: =SUM(IF8:IQ8) | JF8: =SUM(IT8:JE8) | JT8: =SUM(JH8:JS8) | KH8: =SUM(JV8:KG8) | KV8: =SUM(KJ8:KU8)
